Workbook

Sheet AAA Top 50
A1: AAA GAMES U HAVE TO PLAY LIST
A2: TOP 100 • ranks 1–50 are the core must-play tier; ranks 51–100 are the next essential tier • Nintendo excluded
A4: Rank | B4: Game | C4: Year | D4: Publisher / Studio | E4: Genre | F4: Metacritic /100 | G4: Metacritic PC /100 | H4: IGN /10 | I4: GameSpot /10 | J4: PC Gamer /100 | K4: 43.2 | L4: my rating(based on rank) | M4: Why it ranks here
A5: 1 | B5: Red Dead Redemption 2 | C5: 2018 | D5: Rockstar Games | E5: Open-world / Action-Adventure | F5: 97 | G5: 93 | H5: 10 | I5: 9 | K5: =IF((COUNT(F5,G5,J5)+IF(H5="",0,1)+IF(I5="",0,1))=0,"",(SUM(F5,G5,J5)+IF(H5="",0,H5*10)+IF(I5="",0,I5*10))/(COUNT(F5,G5,J5)+IF(H5="",0,1)+IF(I5="",0,1))) -> 95 | L5: =10-((A5-1)*(3/99)) -> 10 | M5: The benchmark blockbuster: world-building, immersion, narrative detail and systemic depth at extraordinary scale.
A6: 2 | B6: Mass Effect 2 | C6: 2010 | D6: BioWare / EA | E6: Action RPG / Sci-Fi | F6: 96 | G6: 94 | H6: 9.6 | I6: 9 | J6: 90 | K6: =IF((COUNT(F6,G6,J6)+IF(H6="",0,1)+IF(I6="",0,1))=0,"",(SUM(F6,G6,J6)+IF(H6="",0,H6*10)+IF(I6="",0,I6*10))/(COUNT(F6,G6,J6)+IF(H6="",0,1)+IF(I6="",0,1))) -> 93.2 | L6: =10-((A6-1)*(3/99)) -> 9.969697 | M6: Elite character-driven sci-fi RPG design; squad relationships and mission structure remain genre-defining.
A7: 3 | B7: The Witcher 3: Wild Hunt | C7: 2015 | D7: CD Projekt Red | E7: Open-world RPG | F7: 92 | G7: 93 | H7: 9.3 | I7: 9 | J7: 92 | K7: =IF((COUNT(F7,G7,J7)+IF(H7="",0,1)+IF(I7="",0,1))=0,"",(SUM(F7,G7,J7)+IF(H7="",0,H7*10)+IF(I7="",0,I7*10))/(COUNT(F7,G7,J7)+IF(H7="",0,1)+IF(I7="",0,1))) -> 92 | L7: =TEXT(10-((A7-1)*(3/99)),"0.0")&" (AI – not played)" -> 9.9 (AI – not played) | M7: A landmark open-world RPG with exceptional side quests, world density and long-term reputation.
A8: 4 | B8: God of War | C8: 2018 | D8: Santa Monica Studio / Sony | E8: Action-Adventure | F8: 94 | G8: 90 | H8: 10 | I8: 9 | J8: 90 | K8: =IF((COUNT(F8,G8,J8)+IF(H8="",0,1)+IF(I8="",0,1))=0,"",(SUM(F8,G8,J8)+IF(H8="",0,H8*10)+IF(I8="",0,I8*10))/(COUNT(F8,G8,J8)+IF(H8="",0,1)+IF(I8="",0,1))) -> 92.8 | L8: =10-((A8-1)*(3/99)) -> 9.9090909 | M8: Major reinvention of a flagship action series with strong combat, presentation and character writing.
A9: 5 | B9: The Last of Us | C9: 2013 | D9: Naughty Dog / Sony | E9: Action-Adventure / Survival | F9: 95 | H9: 10 | I9: 8 | K9: =IF((COUNT(F9,G9,J9)+IF(H9="",0,1)+IF(I9="",0,1))=0,"",(SUM(F9,G9,J9)+IF(H9="",0,H9*10)+IF(I9="",0,I9*10))/(COUNT(F9,G9,J9)+IF(H9="",0,1)+IF(I9="",0,1))) -> 91.666667 | L9: =10-((A9-1)*(3/99)) -> 9.8787879 | M9: A landmark cinematic action game with unusually strong pacing, performances and environmental storytelling.
A10: 6 | B10: Grand Theft Auto V | C10: 2013 | D10: Rockstar Games | E10: Open-world / Action-Adventure | F10: 97 | G10: 96 | H10: 10 | I10: 9 | J10: 93 | K10: =IF((COUNT(F10,G10,J10)+IF(H10="",0,1)+IF(I10="",0,1))=0,"",(SUM(F10,G10,J10)+IF(H10="",0,H10*10)+IF(I10="",0,I10*10))/(COUNT(F10,G10,J10)+IF(H10="",0,1)+IF(I10="",0,1))) -> 95.2 | L10: =10-((A10-1)*(3/99)) -> 9.8484848 | M10: One of the defining blockbuster open worlds; huge cultural footprint and exceptional sandbox freedom.
A11: 7 | B11: Grand Theft Auto IV | C11: 2008 | D11: Rockstar Games | E11: Open-world / Action-Adventure | F11: 98 | G11: 90 | I11: 10 | K11: =IF((COUNT(F11,G11,J11)+IF(H11="",0,1)+IF(I11="",0,1))=0,"",(SUM(F11,G11,J11)+IF(H11="",0,H11*10)+IF(I11="",0,I11*10))/(COUNT(F11,G11,J11)+IF(H11="",0,1)+IF(I11="",0,1))) -> 96 | L11: =TEXT(10-(5*(3/99)),"0.0") -> 9.8 | M11: Massive cultural impact and a more grounded crime-world tone that influenced open-world design.
A12: 8 | B12: Red Dead Redemption | C12: 2010 | D12: Rockstar Games | E12: Open-world / Action-Adventure | F12: 95 | H12: 9.7 | I12: 9.5 | K12: =IF((COUNT(F12,G12,J12)+IF(H12="",0,1)+IF(I12="",0,1))=0,"",(SUM(F12,G12,J12)+IF(H12="",0,H12*10)+IF(I12="",0,I12*10))/(COUNT(F12,G12,J12)+IF(H12="",0,1)+IF(I12="",0,1))) -> 95.666667 | L12: =10-((A12-1)*(3/99)) -> 9.7878788 | M12: Outstanding western open world and a foundational Rockstar story experience.
A13: 9 | B13: BioShock | C13: 2007 | D13: 2K / Irrational Games | E13: FPS / Narrative | F13: 96 | G13: 96 | I13: 9 | J13: 94 | K13: =IF((COUNT(F13,G13,J13)+IF(H13="",0,1)+IF(I13="",0,1))=0,"",(SUM(F13,G13,J13)+IF(H13="",0,H13*10)+IF(I13="",0,I13*10))/(COUNT(F13,G13,J13)+IF(H13="",0,1)+IF(I13="",0,1))) -> 94 | L13: =10-((A13-1)*(3/99)) -> 9.7575758 | M13: A landmark AAA shooter/narrative hybrid whose setting, atmosphere and storytelling still stand out.
A14: 10 | B14: Mass Effect | C14: 2007 | D14: BioWare / EA | E14: Action RPG / Sci-Fi | F14: 91 | I14: 8.5 | J14: 85 | K14: =IF((COUNT(F14,G14,J14)+IF(H14="",0,1)+IF(I14="",0,1))=0,"",(SUM(F14,G14,J14)+IF(H14="",0,H14*10)+IF(I14="",0,I14*10))/(COUNT(F14,G14,J14)+IF(H14="",0,1)+IF(I14="",0,1))) -> 87 | L14: =10-((A14-1)*(3/99)) -> 9.7272727 | M14: Established BioWare's galaxy-scale RPG formula and the Commander Shepard trilogy foundation.
A15: 11 | B15: The Elder Scrolls V: Skyrim | C15: 2011 | D15: Bethesda Game Studios | E15: Open-world RPG | F15: 96 | G15: 94 | H15: 9.5 | I15: 9.5 | J15: 94 | K15: =IF((COUNT(F15,G15,J15)+IF(H15="",0,1)+IF(I15="",0,1))=0,"",(SUM(F15,G15,J15)+IF(H15="",0,H15*10)+IF(I15="",0,I15*10))/(COUNT(F15,G15,J15)+IF(H15="",0,1)+IF(I15="",0,1))) -> 94.8 | L15: =TEXT(10-((A15-1)*(3/99)),"0.0")&" (AI – not played)" -> 9.7 (AI – not played) | M15: Defining open-world fantasy RPG freedom; exploration, modding and scale made it a lasting gateway RPG.
A16: 12 | B16: Baldur's Gate 3 | C16: 2023 | D16: Larian Studios | E16: CRPG / RPG | F16: 96 | G16: 96 | H16: 10 | I16: 10 | J16: 97 | K16: =IF((COUNT(F16,G16,J16)+IF(H16="",0,1)+IF(I16="",0,1))=0,"",(SUM(F16,G16,J16)+IF(H16="",0,H16*10)+IF(I16="",0,I16*10))/(COUNT(F16,G16,J16)+IF(H16="",0,1)+IF(I16="",0,1))) -> 97.8 | L16: =TEXT(10-((A16-1)*(3/99)),"0.0")&" (AI – not played)" -> 9.7 (AI – not played) | M16: A modern RPG landmark for player choice, reactivity, companions, encounter design and systemic freedom.
A17: 13 | B17: Clair Obscur: Expedition 33 | C17: 2025 | D17: Sandfall Interactive / Kepler Interactive | E17: Turn-based RPG | F17: 92 | G17: 91 | H17: 9 | I17: 9 | K17: =IF((COUNT(F17,G17,J17)+IF(H17="",0,1)+IF(I17="",0,1))=0,"",(SUM(F17,G17,J17)+IF(H17="",0,H17*10)+IF(I17="",0,I17*10))/(COUNT(F17,G17,J17)+IF(H17="",0,1)+IF(I17="",0,1))) -> 90.75 | L17: =10-((A17-1)*(3/99)) -> 9.6363636 | M17: Exceptional modern RPG breakout: distinctive world, music, story and an innovative turn-based/action hybrid. AAA-caliber presentation despite an indie-sized studio.
A18: 14 | B18: Batman: Arkham City | C18: 2011 | D18: Rocksteady / WB Games | E18: Action-Adventure | F18: 94 | G18: 94 | H18: 9.5 | I18: 9 | J18: 94 | K18: =IF((COUNT(F18,G18,J18)+IF(H18="",0,1)+IF(I18="",0,1))=0,"",(SUM(F18,G18,J18)+IF(H18="",0,H18*10)+IF(I18="",0,I18*10))/(COUNT(F18,G18,J18)+IF(H18="",0,1)+IF(I18="",0,1))) -> 93.4 | L18: =10-((A18-1)*(3/99)) -> 9.6060606 | M18: The standout Batman game and a benchmark for open-world superhero action.
A19: 15 | B19: Elden Ring | C19: 2022 | D19: FromSoftware / Bandai Namco | E19: Open-world Action RPG | F19: 96 | G19: 94 | H19: 10 | I19: 10 | J19: 95 | K19: =IF((COUNT(F19,G19,J19)+IF(H19="",0,1)+IF(I19="",0,1))=0,"",(SUM(F19,G19,J19)+IF(H19="",0,H19*10)+IF(I19="",0,I19*10))/(COUNT(F19,G19,J19)+IF(H19="",0,1)+IF(I19="",0,1))) -> 97 | L19: =TEXT(10-((A19-1)*(3/99)),"0.0")&" (AI – not played)" -> 9.6 (AI – not played) | M19: Modern action-RPG landmark with huge exploration freedom and influential world design.
A20: 16 | B20: Uncharted 4: A Thief's End | C20: 2016 | D20: Naughty Dog / Sony | E20: Action-Adventure | F20: 93 | I20: 10 | K20: =IF((COUNT(F20,G20,J20)+IF(H20="",0,1)+IF(I20="",0,1))=0,"",(SUM(F20,G20,J20)+IF(H20="",0,H20*10)+IF(I20="",0,I20*10))/(COUNT(F20,G20,J20)+IF(H20="",0,1)+IF(I20="",0,1))) -> 96.5 | L20: =10-((A20-1)*(3/99)) -> 9.5454545 | M20: AAA cinematic adventure polished to an exceptional degree, with superb set pieces and production value.
A21: 17 | B21: God of War Ragnarök | C21: 2022 | D21: Santa Monica Studio / Sony | E21: Action-Adventure | F21: 94 | G21: 94 | H21: 10 | I21: 10 | J21: 90 | K21: =IF((COUNT(F21,G21,J21)+IF(H21="",0,1)+IF(I21="",0,1))=0,"",(SUM(F21,G21,J21)+IF(H21="",0,H21*10)+IF(I21="",0,I21*10))/(COUNT(F21,G21,J21)+IF(H21="",0,1)+IF(I21="",0,1))) -> 95.6 | L21: =10-((A21-1)*(3/99)) -> 9.5151515 | M21: Refined sequel that expands the 2018 formula while delivering some of the strongest modern blockbuster combat.
A22: 18 | B22: The Last of Us Part II | C22: 2020 | D22: Naughty Dog / Sony | E22: Action-Adventure | F22: 93 | I22: 8 | K22: =IF((COUNT(F22,G22,J22)+IF(H22="",0,1)+IF(I22="",0,1))=0,"",(SUM(F22,G22,J22)+IF(H22="",0,H22*10)+IF(I22="",0,I22*10))/(COUNT(F22,G22,J22)+IF(H22="",0,1)+IF(I22="",0,1))) -> 86.5 | L22: =10-((A22-1)*(3/99)) -> 9.4848485 | M22: Bold sequel with elite production, combat depth and unusually ambitious storytelling.
A23: 19 | B23: Grand Theft Auto: San Andreas | C23: 2004 | D23: Rockstar North / Rockstar | E23: Open-world / Action-Adventure | F23: 95 | I23: 9.6 | K23: =IF((COUNT(F23,G23,J23)+IF(H23="",0,1)+IF(I23="",0,1))=0,"",(SUM(F23,G23,J23)+IF(H23="",0,H23*10)+IF(I23="",0,I23*10))/(COUNT(F23,G23,J23)+IF(H23="",0,1)+IF(I23="",0,1))) -> 95.5 | L23: =10-((A23-1)*(3/99)) -> 9.4545455 | M23: An enormous cultural landmark and one of the strongest examples of early 3D open-world freedom.
A24: 20 | B24: Mass Effect 3 | C24: 2012 | D24: BioWare / EA | E24: Action RPG / Sci-Fi | F24: 93 | G24: 89 | H24: 9.5 | I24: 9.5 | J24: 90 | K24: =IF((COUNT(F24,G24,J24)+IF(H24="",0,1)+IF(I24="",0,1))=0,"",(SUM(F24,G24,J24)+IF(H24="",0,H24*10)+IF(I24="",0,I24*10))/(COUNT(F24,G24,J24)+IF(H24="",0,1)+IF(I24="",0,1))) -> 92.4 | L24: =10-((A24-1)*(3/99)) -> 9.4242424 | M24: Excellent RPG systems, companions and galaxy-scale storytelling despite a divisive finale.
A25: 21 | B25: Fallout 3 | C25: 2008 | D25: Bethesda Game Studios | E25: Open-world RPG | F25: 93 | G25: 91 | H25: 9.6 | I25: 9 | J25: 92 | K25: =IF((COUNT(F25,G25,J25)+IF(H25="",0,1)+IF(I25="",0,1))=0,"",(SUM(F25,G25,J25)+IF(H25="",0,H25*10)+IF(I25="",0,I25*10))/(COUNT(F25,G25,J25)+IF(H25="",0,1)+IF(I25="",0,1))) -> 92.4 | L25: =10-((A25-1)*(3/99)) -> 9.3939394 | M25: A foundational modern open-world RPG with exploration, questing and atmosphere still worth experiencing.
A26: 22 | B26: Baldur's Gate II: Shadows of Amn | C26: 2000 | D26: BioWare / Interplay | E26: CRPG / RPG | F26: 95 | I26: 9.6 | K26: =IF((COUNT(F26,G26,J26)+IF(H26="",0,1)+IF(I26="",0,1))=0,"",(SUM(F26,G26,J26)+IF(H26="",0,H26*10)+IF(I26="",0,I26*10))/(COUNT(F26,G26,J26)+IF(H26="",0,1)+IF(I26="",0,1))) -> 95.5 | L26: =TEXT(10-((A26-1)*(3/99)),"0.0")&" (AI – not played)" -> 9.4 (AI – not played) | M26: One of the foundational large-scale RPGs; less modern-looking, but massively important to the genre.
A27: 23 | B27: Halo 3 | C27: 2007 | D27: Bungie / Microsoft | E27: FPS | F27: 94 | I27: 9.5 | K27: =IF((COUNT(F27,G27,J27)+IF(H27="",0,1)+IF(I27="",0,1))=0,"",(SUM(F27,G27,J27)+IF(H27="",0,H27*10)+IF(I27="",0,I27*10))/(COUNT(F27,G27,J27)+IF(H27="",0,1)+IF(I27="",0,1))) -> 94.5 | L27: =10-((A27-1)*(3/99)) -> 9.3333333 | M27: One of the defining console FPS campaigns and a major multiplayer-era blockbuster.
A28: 24 | B28: Portal 2 | C28: 2011 | D28: Valve | E28: Puzzle / Adventure | F28: 95 | G28: 95 | H28: 10 | I28: 10 | J28: 94 | K28: =IF((COUNT(F28,G28,J28)+IF(H28="",0,1)+IF(I28="",0,1))=0,"",(SUM(F28,G28,J28)+IF(H28="",0,H28*10)+IF(I28="",0,I28*10))/(COUNT(F28,G28,J28)+IF(H28="",0,1)+IF(I28="",0,1))) -> 96.8 | L28: =TEXT(10-((A28-1)*(3/99)),"0.0")&" (AI – not played)" -> 9.3 (AI – not played) | M28: One of the strongest puzzle/adventure productions ever released by a major studio.
A29: 25 | B29: Half-Life 2 | C29: 2004 | D29: Valve | E29: FPS / Action | F29: 96 | G29: 96 | H29: 9.7 | I29: 9.2 | J29: 96 | K29: =IF((COUNT(F29,G29,J29)+IF(H29="",0,1)+IF(I29="",0,1))=0,"",(SUM(F29,G29,J29)+IF(H29="",0,H29*10)+IF(I29="",0,I29*10))/(COUNT(F29,G29,J29)+IF(H29="",0,1)+IF(I29="",0,1))) -> 95.4 | L29: =10-((A29-1)*(3/99)) -> 9.2727273 | M29: A transformative FPS that reshaped physics, environmental storytelling and immersive level design.
A30: 26 | B30: Cyberpunk 2077 | C30: 2020 | D30: CD Projekt Red | E30: Open-world RPG | F30: 86 | G30: 86 | H30: 9 | I30: 7 | J30: 78 | K30: =IF((COUNT(F30,G30,J30)+IF(H30="",0,1)+IF(I30="",0,1))=0,"",(SUM(F30,G30,J30)+IF(H30="",0,H30*10)+IF(I30="",0,I30*10))/(COUNT(F30,G30,J30)+IF(H30="",0,1)+IF(I30="",0,1))) -> 82 | L30: =10-((A30-1)*(3/99)) -> 9.2424242 | M30: An ambitious, visually striking RPG whose post-launch evolution is important to its legacy.
A31: 27 | B31: Resident Evil 4 | C31: 2023 | D31: Capcom | E31: Survival Horror / Action | F31: 93 | G31: 91 | H31: 10 | I31: 10 | J31: 80 | K31: =IF((COUNT(F31,G31,J31)+IF(H31="",0,1)+IF(I31="",0,1))=0,"",(SUM(F31,G31,J31)+IF(H31="",0,H31*10)+IF(I31="",0,I31*10))/(COUNT(F31,G31,J31)+IF(H31="",0,1)+IF(I31="",0,1))) -> 92.8 | L31: =10-((A31-1)*(3/99)) -> 9.2121212 | M31: A benchmark survival-horror remake: masterful pacing, encounter design and combat that sharpen an all-time classic.
A32: 28 | B32: Alan Wake 2 | C32: 2023 | D32: Remedy / Epic Games | E32: Survival Horror / Action | F32: 89 | G32: 89 | H32: 9 | I32: 9 | J32: 88 | K32: =IF((COUNT(F32,G32,J32)+IF(H32="",0,1)+IF(I32="",0,1))=0,"",(SUM(F32,G32,J32)+IF(H32="",0,H32*10)+IF(I32="",0,I32*10))/(COUNT(F32,G32,J32)+IF(H32="",0,1)+IF(I32="",0,1))) -> 89.2 | L32: =TEXT(10-((A32-1)*(3/99)),"0.0")&" (AI – not played)" -> 9.2 (AI – not played) | M32: A landmark modern horror production with exceptional audiovisual direction and narrative ambition.
A33: 29 | B33: Control | C33: 2019 | D33: Remedy / 505 Games | E33: Action-Adventure | F33: 85 | G33: 82 | H33: 8.8 | I33: 8 | J33: 88 | K33: =IF((COUNT(F33,G33,J33)+IF(H33="",0,1)+IF(I33="",0,1))=0,"",(SUM(F33,G33,J33)+IF(H33="",0,H33*10)+IF(I33="",0,I33*10))/(COUNT(F33,G33,J33)+IF(H33="",0,1)+IF(I33="",0,1))) -> 84.6 | L33: =10-((A33-1)*(3/99)) -> 9.1515152 | M33: Distinctive AAA supernatural action with exceptional atmosphere, art direction and telekinetic combat.
A34: 30 | B34: Star Wars: Knights of the Old Republic | C34: 2003 | D34: BioWare / LucasArts | E34: RPG | F34: 94 | G34: 94 | H34: 9.2 | I34: 9.1 | J34: 92 | K34: =IF((COUNT(F34,G34,J34)+IF(H34="",0,1)+IF(I34="",0,1))=0,"",(SUM(F34,G34,J34)+IF(H34="",0,H34*10)+IF(I34="",0,I34*10))/(COUNT(F34,G34,J34)+IF(H34="",0,1)+IF(I34="",0,1))) -> 92.6 | L34: =TEXT(10-((A34-1)*(3/99)),"0.0")&" (AI – not played)" -> 9.1 (AI – not played) | M34: A landmark licensed RPG with strong writing, choice and world-building.
A35: 31 | B35: Metal Gear Solid 3: Snake Eater | C35: 2004 | D35: Konami | E35: Action / Stealth | F35: 91 | I35: 9 | K35: =IF((COUNT(F35,G35,J35)+IF(H35="",0,1)+IF(I35="",0,1))=0,"",(SUM(F35,G35,J35)+IF(H35="",0,H35*10)+IF(I35="",0,I35*10))/(COUNT(F35,G35,J35)+IF(H35="",0,1)+IF(I35="",0,1))) -> 90.5 | L35: =10-((A35-1)*(3/99)) -> 9.0909091 | M35: A landmark stealth blockbuster with exceptional survival mechanics and storytelling.
A36: 32 | B36: Call of Duty 4: Modern Warfare | C36: 2007 | D36: Infinity Ward / Activision | E36: FPS | F36: 94 | G36: 92 | H36: 9.4 | I36: 9 | K36: =IF((COUNT(F36,G36,J36)+IF(H36="",0,1)+IF(I36="",0,1))=0,"",(SUM(F36,G36,J36)+IF(H36="",0,H36*10)+IF(I36="",0,I36*10))/(COUNT(F36,G36,J36)+IF(H36="",0,1)+IF(I36="",0,1))) -> 92.5 | L36: =10-((A36-1)*(3/99)) -> 9.0606061 | M36: A defining AAA shooter whose campaign, multiplayer and presentation changed the mainstream FPS.
A37: 33 | B37: Assassin's Creed IV: Black Flag | C37: 2013 | D37: Ubisoft Montreal / Ubisoft | E37: Open-world Action-Adventure | F37: 88 | G37: 84 | H37: 9 | I37: 9 | J37: 86 | K37: =IF((COUNT(F37,G37,J37)+IF(H37="",0,1)+IF(I37="",0,1))=0,"",(SUM(F37,G37,J37)+IF(H37="",0,H37*10)+IF(I37="",0,I37*10))/(COUNT(F37,G37,J37)+IF(H37="",0,1)+IF(I37="",0,1))) -> 87.6 | L37: =10-((A37-1)*(3/99)) -> 9.030303 | M37: Combines Assassin's Creed with a highly memorable open-world naval sandbox.
A38: 34 | B38: Dishonored | C38: 2012 | D38: Arkane / Bethesda | E38: Immersive Sim / Action | F38: 88 | G38: 88 | H38: 9.2 | I38: 9 | J38: 88 | K38: =IF((COUNT(F38,G38,J38)+IF(H38="",0,1)+IF(I38="",0,1))=0,"",(SUM(F38,G38,J38)+IF(H38="",0,H38*10)+IF(I38="",0,I38*10))/(COUNT(F38,G38,J38)+IF(H38="",0,1)+IF(I38="",0,1))) -> 89.2 | L38: =TEXT(10-((A38-1)*(3/99)),"0.0")&" (AI – not played)" -> 9.0 (AI – not played) | M38: A landmark modern immersive sim with excellent level design and player-driven approaches.
A39: 35 | B39: The Elder Scrolls IV: Oblivion | C39: 2006 | D39: Bethesda Game Studios | E39: Open-world RPG | F39: 94 | G39: 94 | H39: 9.3 | I39: 9.5 | J39: 92 | K39: =IF((COUNT(F39,G39,J39)+IF(H39="",0,1)+IF(I39="",0,1))=0,"",(SUM(F39,G39,J39)+IF(H39="",0,H39*10)+IF(I39="",0,I39*10))/(COUNT(F39,G39,J39)+IF(H39="",0,1)+IF(I39="",0,1))) -> 93.6 | L39: =10-((A39-1)*(3/99)) -> 8.969697 | M39: One of the key early open-world RPGs and a direct ancestor to Skyrim.
A40: 36 | B40: Halo: Reach | C40: 2010 | D40: Bungie / Microsoft | E40: FPS | F40: 91 | I40: 9.5 | K40: =IF((COUNT(F40,G40,J40)+IF(H40="",0,1)+IF(I40="",0,1))=0,"",(SUM(F40,G40,J40)+IF(H40="",0,H40*10)+IF(I40="",0,I40*10))/(COUNT(F40,G40,J40)+IF(H40="",0,1)+IF(I40="",0,1))) -> 93 | L40: =10-((A40-1)*(3/99)) -> 8.9393939 | M40: Excellent campaign pacing, combat and world-building within the Halo formula.
A41: 37 | B41: Far Cry 4 | C41: 2014 | D41: Ubisoft Montreal / Ubisoft | E41: Open-world FPS | F41: 80 | G41: 80 | H41: 8.5 | I41: 8.5 | J41: 80 | K41: =IF((COUNT(F41,G41,J41)+IF(H41="",0,1)+IF(I41="",0,1))=0,"",(SUM(F41,G41,J41)+IF(H41="",0,H41*10)+IF(I41="",0,I41*10))/(COUNT(F41,G41,J41)+IF(H41="",0,1)+IF(I41="",0,1))) -> 82 | L41: =10-((A41-1)*(3/99)) -> 8.9090909 | M41: Big, polished Ubisoft open world; less groundbreaking than FC3 but still a core AAA shooter experience.
...

Sheet Posters
A1: BIG-TITLE POSTERS
A2: Representative covers; one version per title.
A4: Red Dead Redemption 2 | E4: Mass Effect 2
A19: Grand Theft Auto V | E19: God of War
A34: BioShock | E34: The Witcher 3: Wild Hunt
A49: The Last of Us | E49: Elden Ring
A64: Clair Obscur: Expedition 33

Sheet Timeline
A1: AAA TOP 100 — RELEASE TIMELINE
A3: Year | B3: Rank | C3: Game | D3: Tier | E3: Year | F3: Rank | G3: Game | H3: Tier
A4: 2000 | B4: 22 | C4: Baldur's Gate II: Shadows of Amn | D4: TOP 50 | E4: 2016 | F4: 41 | G4: Titanfall 2 | H4: TOP 50
A5: 2000 | B5: 59 | C5: Diablo II | D5: BOTTOM 50 | E5: 2016 | F5: 56 | G5: Final Fantasy XV | H5: BOTTOM 50
A6: 2002 | B6: 45 | C6: Grand Theft Auto: Vice City | D6: TOP 50 | E6: 2016 | F6: 64 | G6: Overwatch | H6: BOTTOM 50
A7: 2002 | B7: 63 | C7: Warcraft III: Reign of Chaos | D7: BOTTOM 50 | E7: 2016 | F7: 68 | G7: Battlefield 1 | H7: BOTTOM 50
A8: 2003 | B8: 30 | C8: Star Wars: Knights of the Old Republic | D8: TOP 50 | E8: 2016 | F8: 73 | G8: Hitman: World of Assassination | H8: BOTTOM 50
A9: 2004 | B9: 19 | C9: Grand Theft Auto: San Andreas | D9: TOP 50 | E9: 2016 | F9: 74 | G9: Dishonored 2 | H9: BOTTOM 50
A10: 2004 | B10: 25 | C10: Half-Life 2 | D10: TOP 50 | E10: 2016 | F10: 88 | G10: The Division | H10: BOTTOM 50
A11: 2004 | B11: 31 | C11: Metal Gear Solid 3: Snake Eater | D11: TOP 50 | E11: 2016 | F11: 93 | G11: Watch Dogs 2 | H11: BOTTOM 50
A12: 2004 | B12: 61 | C12: World of Warcraft | D12: BOTTOM 50 | E12: 2017 | F12: 27 | G12: Resident Evil 7: Biohazard | H12: TOP 50
A13: 2005 | B13: 57 | C13: Kingdom Hearts II | D13: BOTTOM 50 | E13: 2017 | F13: 42 | G13: Star Wars Battlefront II | H13: TOP 50
A14: 2006 | B14: 35 | C14: The Elder Scrolls IV: Oblivion | D14: TOP 50 | E14: 2017 | F14: 47 | G14: Horizon Zero Dawn | H14: TOP 50
A15: 2007 | B15: 5 | C15: BioShock | D15: TOP 50 | E15: 2017 | F15: 58 | G15: NieR:Automata | H15: BOTTOM 50
... A53: 2016 | B53: 16 | C53: Uncharted 4: A Thief's End | D53: TOP 50 | E53: 2025 | F53: 53 | G53: Death Stranding 2: On the Beach | H53: BOTTOM 50

Sheet Methodology
A3: Scope | B3: Mainstream AAA / blockbuster / major-publisher flagship games, plus a small number of AAA-caliber premium exceptions that clearly belong in an essential modern-gaming list. Nintendo excluded. | D3: Rank | E3: Game | F3: Year
A4: Ranking | B4: Curated must-play ranking, not a raw Metacritic leaderboard. | D4: 1 | E4: Red Dead Redemption 2 | F4: 2018
A5: Primary ranking signals | B5: Critical acclaim, lasting reputation, industry influence, cultural impact, design quality, production ambition and “must-play” status. | D5: 2 | E5: Mass Effect 2 | F5: 2010
A6: Top 50 vs Bottom 50 | B6: Ranks 1–50 are the core list. Ranks 51–100 are the next essential tier and are separated below. | D6: 3 | E6: The Witcher 3: Wild Hunt | F6: 2015
A7: Review scores | B7: Native scales are retained where practical: /100 for Metacritic/PC Gamer and /10 for IGN/GameSpot. | D7: 4 | E7: Grand Theft Auto V | F7: 2013
A8: PC scores | B8: Metacritic PC is separated where a distinct PC metascore exists; blanks mean no separate value was carried into this snapshot. | D8: 5 | E8: BioShock | F8: 2007
A9: Normalized Avg /100 | B9: Converts /10 scores to /100 and averages available numeric critic scores. Supporting metric only. | D9: 6 | E9: God of War | F9: 2018
A10: my rating(based on rank) | B10: Rank 1 = 10.0; Rank 100 = 7.0, linearly decreasing across all 100 ranks. It reflects the curated ranking, not a separate review. | D10: 7 | E10: The Last of Us | F10: 2013
A11: Nintendo | B11: No Nintendo titles are included, so there is no redundant Yes/No column. | D11: 8 | E11: Grand Theft Auto IV | F11: 2008
D12: 9 | E12: Red Dead Redemption | F12: 2010
D13: 10 | E13: Mass Effect | F13: 2007

Sheet Sortable Ratings
A1: Rank | B1: Game | C1: Metacritic /100 | D1: Metacritic PC /100 | E1: IGN /10 | F1: GameSpot /10 | G1: PC Gamer /100 | H1: Normalized Avg /100 | I1: My rating
A2: ='AAA Top 50'!A5 -> 1 | B2: ='AAA Top 50'!B5 -> Red Dead Redemption 2 | C2: ='AAA Top 50'!F5 -> 97 | D2: ='AAA Top 50'!G5 -> 93 | E2: ='AAA Top 50'!H5 -> 10 | F2: ='AAA Top 50'!I5 -> 9 | G2: ='AAA Top 50'!J5 -> 0 | H2: ='AAA Top 50'!K5 -> 95 | I2: ='AAA Top 50'!L5 -> 10
A3: ='AAA Top 50'!A6 -> 2 | B3: ='AAA Top 50'!B6 -> Mass Effect 2 | C3: ='AAA Top 50'!F6 -> 96 | D3: ='AAA Top 50'!G6 -> 94 | E3: ='AAA Top 50'!H6 -> 9.6 | F3: ='AAA Top 50'!I6 -> 9 | G3: ='AAA Top 50'!J6 -> 90 | H3: ='AAA Top 50'!K6 -> 93.2 | I3: ='AAA Top 50'!L6 -> 9.969697
A4: ='AAA Top 50'!A7 -> 3 | B4: ='AAA Top 50'!B7 -> The Witcher 3: Wild Hunt | C4: ='AAA Top 50'!F7 -> 92 | D4: ='AAA Top 50'!G7 -> 93 | E4: ='AAA Top 50'!H7 -> 9.3 | F4: ='AAA Top 50'!I7 -> 9 | G4: ='AAA Top 50'!J7 -> 92 | H4: ='AAA Top 50'!K7 -> 92 | I4: ='AAA Top 50'!L7 -> 9.9 (AI – not played)
A5: ='AAA Top 50'!A8 -> 4 | B5: ='AAA Top 50'!B8 -> God of War | C5: ='AAA Top 50'!F8 -> 94 | D5: ='AAA Top 50'!G8 -> 90 | E5: ='AAA Top 50'!H8 -> 10 | F5: ='AAA Top 50'!I8 -> 9 | G5: ='AAA Top 50'!J8 -> 90 | H5: ='AAA Top 50'!K8 -> 92.8 | I5: ='AAA Top 50'!L8 -> 9.9090909
A6: ='AAA Top 50'!A9 -> 5 | B6: ='AAA Top 50'!B9 -> The Last of Us | C6: ='AAA Top 50'!F9 -> 95 | D6: ='AAA Top 50'!G9 -> 0 | E6: ='AAA Top 50'!H9 -> 10 | F6: ='AAA Top 50'!I9 -> 8 | G6: ='AAA Top 50'!J9 -> 0 | H6: ='AAA Top 50'!K9 -> 91.666667 | I6: ='AAA Top 50'!L9 -> 9.8787879
A7: ='AAA Top 50'!A10 -> 6 | B7: ='AAA Top 50'!B10 -> Grand Theft Auto V | C7: ='AAA Top 50'!F10 -> 97 | D7: ='AAA Top 50'!G10 -> 96 | E7: ='AAA Top 50'!H10 -> 10 | F7: ='AAA Top 50'!I10 -> 9 | G7: ='AAA Top 50'!J10 -> 93 | H7: ='AAA Top 50'!K10 -> 95.2 | I7: ='AAA Top 50'!L10 -> 9.8484848
A8: ='AAA Top 50'!A11 -> 7 | B8: ='AAA Top 50'!B11 -> Grand Theft Auto IV | C8: ='AAA Top 50'!F11 -> 98 | D8: ='AAA Top 50'!G11 -> 90 | E8: ='AAA Top 50'!H11 -> 0 | F8: ='AAA Top 50'!I11 -> 10 | G8: ='AAA Top 50'!J11 -> 0 | H8: ='AAA Top 50'!K11 -> 96 | I8: ='AAA Top 50'!L11 -> 9.8
A9: ='AAA Top 50'!A12 -> 8 | B9: ='AAA Top 50'!B12 -> Red Dead Redemption | C9: ='AAA Top 50'!F12 -> 95 | D9: ='AAA Top 50'!G12 -> 0 | E9: ='AAA Top 50'!H12 -> 9.7 | F9: ='AAA Top 50'!I12 -> 9.5 | G9: ='AAA Top 50'!J12 -> 0 | H9: ='AAA Top 50'!K12 -> 95.666667 | I9: ='AAA Top 50'!L12 -> 9.7878788
A10: ='AAA Top 50'!A13 -> 9 | B10: ='AAA Top 50'!B13 -> BioShock | C10: ='AAA Top 50'!F13 -> 96 | D10: ='AAA Top 50'!G13 -> 96 | E10: ='AAA Top 50'!H13 -> 0 | F10: ='AAA Top 50'!I13 -> 9 | G10: ='AAA Top 50'!J13 -> 94 | H10: ='AAA Top 50'!K13 -> 94 | I10: ='AAA Top 50'!L13 -> 9.7575758
A11: ='AAA Top 50'!A14 -> 10 | B11: ='AAA Top 50'!B14 -> Mass Effect | C11: ='AAA Top 50'!F14 -> 91 | D11: ='AAA Top 50'!G14 -> 0 | E11: ='AAA Top 50'!H14 -> 0 | F11: ='AAA Top 50'!I14 -> 8.5 | G11: ='AAA Top 50'!J14 -> 85 | H11: ='AAA Top 50'!K14 -> 87 | I11: ='AAA Top 50'!L14 -> 9.7272727
A12: ='AAA Top 50'!A15 -> 11 | B12: ='AAA Top 50'!B15 -> The Elder Scrolls V: Skyrim | C12: ='AAA Top 50'!F15 -> 96 | D12: ='AAA Top 50'!G15 -> 94 | E12: ='AAA Top 50'!H15 -> 9.5 | F12: ='AAA Top 50'!I15 -> 9.5 | G12: ='AAA Top 50'!J15 -> 94 | H12: ='AAA Top 50'!K15 -> 94.8 | I12: ='AAA Top 50'!L15 -> 9.7 (AI – not played)
A13: ='AAA Top 50'!A16 -> 12 | B13: ='AAA Top 50'!B16 -> Baldur's Gate 3 | C13: ='AAA Top 50'!F16 -> 96 | D13: ='AAA Top 50'!G16 -> 96 | E13: ='AAA Top 50'!H16 -> 10 | F13: ='AAA Top 50'!I16 -> 10 | G13: ='AAA Top 50'!J16 -> 97 | H13: ='AAA Top 50'!K16 -> 97.8 | I13: ='AAA Top 50'!L16 -> 9.7 (AI – not played)
... A51: ='AAA Top 50'!A54 -> 50 | B51: ='AAA Top 50'!B54 -> Ghost of Tsushima | C51: ='AAA Top 50'!F54 -> 83 | D51: ='AAA Top 50'!G54 -> 87 | E51: ='AAA Top 50'!H54 -> 9 | F51: ='AAA Top 50'!I54 -> 7 | G51: ='AAA Top 50'!J54 -> 87 | H51: ='AAA Top 50'!K54 -> 83.4 | I51: ='AAA Top 50'!L54 -> 8.5151515
A52: ='AAA Top 50'!A56 -> 51 | B52: ='AAA Top 50'!B56 -> DOOM Eternal | C52: ='AAA Top 50'!F56 -> 88 | D52: ='AAA Top 50'!G56 -> 88 | E52: ='AAA Top 50'!H56 -> 9 | F52: ='AAA Top 50'!I56 -> 8 | G52: ='AAA Top 50'!J56 -> 94 | H52: ='AAA Top 50'!K56 -> 88 | I52: ='AAA Top 50'!L56 -> 8.4848485
A53: ='AAA Top 50'!A57 -> 52 | B53: ='AAA Top 50'!B57 -> Star Wars Jedi: Survivor | C53: ='AAA Top 50'!F57 -> 85 | D53: ='AAA Top 50'!G57 -> 79 | E53: ='AAA Top 50'!H57 -> 9 | F53: ='AAA Top 50'!I57 -> 9 | G53: ='AAA Top 50'!J57 -> 85 | H53: ='AAA Top 50'!K57 -> 85.8 | I53: ='AAA Top 50'!L57 -> 8.4545455
A54: ='AAA Top 50'!A58 -> 53 | B54: ='AAA Top 50'!B58 -> Death Stranding | C54: ='AAA Top 50'!F58 -> 82 | D54: ='AAA Top 50'!G58 -> 85 | E54: ='AAA Top 50'!H58 -> 6.8 | F54: ='AAA Top 50'!I58 -> 9 | G54: ='AAA Top 50'!J58 -> 83 | H54: ='AAA Top 50'!K58 -> 81.6 | I54: ='AAA Top 50'!L58 -> 8.4242424
A55: ='AAA Top 50'!A59 -> 54 | B55: ='AAA Top 50'!B59 -> Death Stranding 2: On the Beach | C55: ='AAA Top 50'!F59 -> 90 | D55: ='AAA Top 50'!G59 -> 90 | E55: ='AAA Top 50'!H59 -> 9 | F55: ='AAA Top 50'!I59 -> 9 | G55: ='AAA Top 50'!J59 -> 90 | H55: ='AAA Top 50'!K59 -> 90 | I55: ='AAA Top 50'!L59 -> 8.3939394
A56: ='AAA Top 50'!A60 -> 55 | B56: ='AAA Top 50'!B60 -> Final Fantasy VII Remake | C56: ='AAA Top 50'!F60 -> 87 | D56: ='AAA Top 50'!G60 -> 89 | E56: ='AAA Top 50'!H60 -> 8 | F56: ='AAA Top 50'!I60 -> 8 | G56: ='AAA Top 50'!J60 -> 80 | H56: ='AAA Top 50'!K60 -> 83.2 | I56: ='AAA Top 50'!L60 -> 8.3636364
A57: ='AAA Top 50'!A61 -> 56 | B57: ='AAA Top 50'!B61 -> Final Fantasy XVI | C57: ='AAA Top 50'!F61 -> 87 | D57: ='AAA Top 50'!G61 -> 89 | E57: ='AAA Top 50'!H61 -> 9 | F57: ='AAA Top 50'!I61 -> 9 | G57: ='AAA Top 50'!J61 -> 80 | H57: ='AAA Top 50'!K61 -> 87.2 | I57: ='AAA Top 50'!L61 -> 8.3333333
A58: ='AAA Top 50'!A62 -> 57 | B58: ='AAA Top 50'!B62 -> Final Fantasy XV | C58: ='AAA Top 50'!F62 -> 81 | D58: ='AAA Top 50'!G62 -> 82 | E58: ='AAA Top 50'!H62 -> 0 | F58: ='AAA Top 50'!I62 -> 8 | G58: ='AAA Top 50'!J62 -> 85 | H58: ='AAA Top 50'!K62 -> 82 | I58: ='AAA Top 50'!L62 -> 8.3030303
A59: ='AAA Top 50'!A63 -> 58 | B59: ='AAA Top 50'!B63 -> Kingdom Hearts II | C59: ='AAA Top 50'!F63 -> 87 | D59: ='AAA Top 50'!G63 -> 0 | E59: ='AAA Top 50'!H63 -> 9 | F59: ='AAA Top 50'!I63 -> 9 | G59: ='AAA Top 50'!J63 -> 0 | H59: ='AAA Top 50'!K63 -> 89 | I59: ='AAA Top 50'!L63 -> 8.2727273
A60: ='AAA Top 50'!A64 -> 59 | B60: ='AAA Top 50'!B64 -> NieR:Automata | C60: ='AAA Top 50'!F64 -> 88 | D60: ='AAA Top 50'!G64 -> 84 | E60: ='AAA Top 50'!H64 -> 0 | F60: ='AAA Top 50'!I64 -> 8 | G60: ='AAA Top 50'!J64 -> 87 | H60: ='AAA Top 50'!K64 -> 84.75 | I60: ='AAA Top 50'!L64 -> 8.2424242
A61: ='AAA Top 50'!A65 -> 60 | B61: ='AAA Top 50'!B65 -> Diablo II | C61: ='AAA Top 50'!F65 -> 88 | D61: ='AAA Top 50'!G65 -> 0 | E61: ='AAA Top 50'!H65 -> 9 | F61: ='AAA Top 50'!I65 -> 9 | G61: ='AAA Top 50'!J65 -> 0 | H61: ='AAA Top 50'!K65 -> 89.333333 | I61: ='AAA Top 50'!L65 -> 8.2121212
A62: ='AAA Top 50'!A66 -> 61 | B62: ='AAA Top 50'!B66 -> Diablo IV | C62: ='AAA Top 50'!F66 -> 91 | D62: ='AAA Top 50'!G66 -> 90 | E62: ='AAA Top 50'!H66 -> 0 | F62: ='AAA Top 50'!I66 -> 9 | G62: ='AAA Top 50'!J66 -> 86 | H62: ='AAA Top 50'!K66 -> 89.25 | I62: ='AAA Top 50'!L66 -> 8.1818182
A63: ='AAA Top 50'!A67 -> 62 | B63: ='AAA Top 50'!B67 -> World of Warcraft | C63: ='AAA Top 50'!F67 -> 93 | D63: ='AAA Top 50'!G67 -> 0 | E63: ='AAA Top 50'!H67 -> 9.5 | F63: ='AAA Top 50'!I67 -> 9 | G63: ='AAA Top 50'!J67 -> 0 | H63: ='AAA Top 50'!K67 -> 92.666667 | I63: ='AAA Top 50'!L67 -> 8.1515152
... A101: ='AAA Top 50'!A105 -> 100 | B101: ='AAA Top 50'!B105 -> L.A. Noire | C101: ='AAA Top 50'!F105 -> 83 | D101: ='AAA Top 50'!G105 -> 83 | E101: ='AAA Top 50'!H105 -> 8.5 | F101: ='AAA Top 50'!I105 -> 7.5 | G101: ='AAA Top 50'!J105 -> 82 | H101: ='AAA Top 50'!K105 -> 81.6 | I101: ='AAA Top 50'!L105 -> 7
