Workbook

Sheet Start Here
A1: PLAY 100
A3: A collection worth making time for.
A6: 100 essential gaming experiences, in your curated order. A core 50. A next-essential 50. One collection.
K10: 01 / RED DEAD REDEMPTION 2
A12: 100 | E12: 50 + 50 | I12: 2000–2026 | M12: 100
A14: CURATED ENTRIES | E14: CORE + ESSENTIAL | I14: SOURCE YEARS | M14: SUPPLIED COVERS
A16: EXPLORE THE COLLECTION
A18: 01 THE 100 → | I18: 02 CHRONOLOGY →
A20: Filter by tier, year, studio, genre or score. Rank and Game stay frozen. | I20: The full collection ordered by source year, with the curated rank intact.
A23: 03 COVER GALLERY → | I23: 04 METHODOLOGY →
A25: Every supplied cover, with a link back to its entry. No downloaded replacements. | I25: What each number means, what remains unknown, and how the source was reconciled.
A29: READ THE NUMBERS CORRECTLY
A31: CURATED RANK The order is the source collection's must-play ranking—not a critic leaderboard. | E31: CRITIC SNAPSHOT Scores retain their native /100 or /10 scales. No current verification or score date is claimed. | I31: AVAILABLE, NOT ZERO Blank critic cells are unknown. Averages skip blanks and normalize /10 entries to /100. | M31: LEUL'S ORIGINAL RATING Leul's rating /10 comes from his original rank-based column. Exact cached values and source notes are preserved.
A37: Both Metacritic columns count when entered. The critic average describes available score columns, not independent publications. It supports browsing; it never determines the order.
A42: Twelve original ratings explicitly carry Leul's source annotation “(AI – not played)”. The numeric rating and the exact note are both preserved. These historical author notes never set a website visitor's played status.
A47: Mainstream AAA / blockbuster / major-publisher flagship games, plus a small number of AAA-caliber premium exceptions that clearly belong in an essential modern-gaming list. Nintendo excluded.
A52: SOURCE / AAA_games_u_have_to_play_list_top_100.xlsx The primary list is authoritative. Stale side tables were reconciled; native score entries were not rewritten. See Methodology and artifact-manifest.json for the complete provenance.
A57: Curated by Leul Tewodros Agonafer
A58: GitHub · LeulTew/play-100 | F58: LinkedIn · Leul Tewodros Agonafer | K58: Telegram · @fabbin

Sheet The 100
A1: THE 100
A2: Curated order, not a critic leaderboard. Core = ranks 1–50 · Essential = ranks 51–100 · Nintendo excluded.
A4: ← Start Here | C4: Chronology → | F4: Covers → | I4: Methodology →
A5: Leul's original rating is copied from his original rank-based column, including rounded/text caches. Critic snapshots stay separate. Rank + Game stay frozen.
A6: Rank | B6: Game | C6: Tier | D6: Year | E6: Publisher / Studio | F6: Genre | G6: Metacritic /100 | H6: Metacritic PC /100 | I6: IGN /10 | J6: GameSpot /10 | K6: PC Gamer /100 | L6: Critic average /100 | M6: Leul's original rating /10 | N6: Source note | O6: Why it ranks here | P6: Cover
A7: 1 | B7: Red Dead Redemption 2 | C7: Core | D7: 2018 | E7: Rockstar Games | F7: Open-world / Action-Adventure | G7: 97 | H7: 93 | I7: 10 | J7: 9 | L7: =IF(COUNT(G7:K7)=0,"",(SUM(G7:H7,K7)+10*SUM(I7:J7))/COUNT(G7:K7)) -> 95 | M7: 10 | O7: The benchmark blockbuster: world-building, immersion, narrative detail and systemic depth at extraordinary scale. | P7: View cover
A8: 2 | B8: Mass Effect 2 | C8: Core | D8: 2010 | E8: BioWare / EA | F8: Action RPG / Sci-Fi | G8: 96 | H8: 94 | I8: 9.6 | J8: 9 | K8: 90 | L8: =IF(COUNT(G8:K8)=0,"",(SUM(G8:H8,K8)+10*SUM(I8:J8))/COUNT(G8:K8)) -> 93.2 | M8: 9.969697 | O8: Elite character-driven sci-fi RPG design; squad relationships and mission structure remain genre-defining. | P8: View cover
A9: 3 | B9: The Witcher 3: Wild Hunt | C9: Core | D9: 2015 | E9: CD Projekt Red | F9: Open-world RPG | G9: 92 | H9: 93 | I9: 9.3 | J9: 9 | K9: 92 | L9: =IF(COUNT(G9:K9)=0,"",(SUM(G9:H9,K9)+10*SUM(I9:J9))/COUNT(G9:K9)) -> 92 | M9: 9.9 | N9: (AI – not played) | O9: A landmark open-world RPG with exceptional side quests, world density and long-term reputation. | P9: View cover
A10: 4 | B10: God of War | C10: Core | D10: 2018 | E10: Santa Monica Studio / Sony | F10: Action-Adventure | G10: 94 | H10: 90 | I10: 10 | J10: 9 | K10: 90 | L10: =IF(COUNT(G10:K10)=0,"",(SUM(G10:H10,K10)+10*SUM(I10:J10))/COUNT(G10:K10)) -> 92.8 | M10: 9.9090909 | O10: Major reinvention of a flagship action series with strong combat, presentation and character writing. | P10: View cover
A11: 5 | B11: The Last of Us | C11: Core | D11: 2013 | E11: Naughty Dog / Sony | F11: Action-Adventure / Survival | G11: 95 | I11: 10 | J11: 8 | L11: =IF(COUNT(G11:K11)=0,"",(SUM(G11:H11,K11)+10*SUM(I11:J11))/COUNT(G11:K11)) -> 91.666667 | M11: 9.8787879 | O11: A landmark cinematic action game with unusually strong pacing, performances and environmental storytelling. | P11: View cover
A12: 6 | B12: Grand Theft Auto V | C12: Core | D12: 2013 | E12: Rockstar Games | F12: Open-world / Action-Adventure | G12: 97 | H12: 96 | I12: 10 | J12: 9 | K12: 93 | L12: =IF(COUNT(G12:K12)=0,"",(SUM(G12:H12,K12)+10*SUM(I12:J12))/COUNT(G12:K12)) -> 95.2 | M12: 9.8484848 | O12: One of the defining blockbuster open worlds; huge cultural footprint and exceptional sandbox freedom. | P12: View cover
A13: 7 | B13: Grand Theft Auto IV | C13: Core | D13: 2008 | E13: Rockstar Games | F13: Open-world / Action-Adventure | G13: 98 | H13: 90 | J13: 10 | L13: =IF(COUNT(G13:K13)=0,"",(SUM(G13:H13,K13)+10*SUM(I13:J13))/COUNT(G13:K13)) -> 96 | M13: 9.8 | O13: Massive cultural impact and a more grounded crime-world tone that influenced open-world design. | P13: View cover
A14: 8 | B14: Red Dead Redemption | C14: Core | D14: 2010 | E14: Rockstar Games | F14: Open-world / Action-Adventure | G14: 95 | I14: 9.7 | J14: 9.5 | L14: =IF(COUNT(G14:K14)=0,"",(SUM(G14:H14,K14)+10*SUM(I14:J14))/COUNT(G14:K14)) -> 95.666667 | M14: 9.7878788 | O14: Outstanding western open world and a foundational Rockstar story experience. | P14: View cover
A15: 9 | B15: BioShock | C15: Core | D15: 2007 | E15: 2K / Irrational Games | F15: FPS / Narrative | G15: 96 | H15: 96 | J15: 9 | K15: 94 | L15: =IF(COUNT(G15:K15)=0,"",(SUM(G15:H15,K15)+10*SUM(I15:J15))/COUNT(G15:K15)) -> 94 | M15: 9.7575758 | O15: A landmark AAA shooter/narrative hybrid whose setting, atmosphere and storytelling still stand out. | P15: View cover
A16: 10 | B16: Mass Effect | C16: Core | D16: 2007 | E16: BioWare / EA | F16: Action RPG / Sci-Fi | G16: 91 | J16: 8.5 | K16: 85 | L16: =IF(COUNT(G16:K16)=0,"",(SUM(G16:H16,K16)+10*SUM(I16:J16))/COUNT(G16:K16)) -> 87 | M16: 9.7272727 | O16: Established BioWare's galaxy-scale RPG formula and the Commander Shepard trilogy foundation. | P16: View cover
A17: 11 | B17: The Elder Scrolls V: Skyrim | C17: Core | D17: 2011 | E17: Bethesda Game Studios | F17: Open-world RPG | G17: 96 | H17: 94 | I17: 9.5 | J17: 9.5 | K17: 94 | L17: =IF(COUNT(G17:K17)=0,"",(SUM(G17:H17,K17)+10*SUM(I17:J17))/COUNT(G17:K17)) -> 94.8 | M17: 9.7 | N17: (AI – not played) | O17: Defining open-world fantasy RPG freedom; exploration, modding and scale made it a lasting gateway RPG. | P17: View cover
A18: 12 | B18: Baldur's Gate 3 | C18: Core | D18: 2023 | E18: Larian Studios | F18: CRPG / RPG | G18: 96 | H18: 96 | I18: 10 | J18: 10 | K18: 97 | L18: =IF(COUNT(G18:K18)=0,"",(SUM(G18:H18,K18)+10*SUM(I18:J18))/COUNT(G18:K18)) -> 97.8 | M18: 9.7 | N18: (AI – not played) | O18: A modern RPG landmark for player choice, reactivity, companions, encounter design and systemic freedom. | P18: View cover
A19: 13 | B19: Clair Obscur: Expedition 33 | C19: Core | D19: 2025 | E19: Sandfall Interactive / Kepler Interactive | F19: Turn-based RPG | G19: 92 | H19: 91 | I19: 9 | J19: 9 | L19: =IF(COUNT(G19:K19)=0,"",(SUM(G19:H19,K19)+10*SUM(I19:J19))/COUNT(G19:K19)) -> 90.75 | M19: 9.6363636 | O19: Exceptional modern RPG breakout: distinctive world, music, story and an innovative turn-based/action hybrid. AAA-caliber presentation despite an indie-sized studio. | P19: View cover
A20: 14 | B20: Batman: Arkham City | C20: Core | D20: 2011 | E20: Rocksteady / WB Games | F20: Action-Adventure | G20: 94 | H20: 94 | I20: 9.5 | J20: 9 | K20: 94 | L20: =IF(COUNT(G20:K20)=0,"",(SUM(G20:H20,K20)+10*SUM(I20:J20))/COUNT(G20:K20)) -> 93.4 | M20: 9.6060606 | O20: The standout Batman game and a benchmark for open-world superhero action. | P20: View cover
A21: 15 | B21: Elden Ring | C21: Core | D21: 2022 | E21: FromSoftware / Bandai Namco | F21: Open-world Action RPG | G21: 96 | H21: 94 | I21: 10 | J21: 10 | K21: 95 | L21: =IF(COUNT(G21:K21)=0,"",(SUM(G21:H21,K21)+10*SUM(I21:J21))/COUNT(G21:K21)) -> 97 | M21: 9.6 | N21: (AI – not played) | O21: Modern action-RPG landmark with huge exploration freedom and influential world design. | P21: View cover
A22: 16 | B22: Uncharted 4: A Thief's End | C22: Core | D22: 2016 | E22: Naughty Dog / Sony | F22: Action-Adventure | G22: 93 | J22: 10 | L22: =IF(COUNT(G22:K22)=0,"",(SUM(G22:H22,K22)+10*SUM(I22:J22))/COUNT(G22:K22)) -> 96.5 | M22: 9.5454545 | O22: AAA cinematic adventure polished to an exceptional degree, with superb set pieces and production value. | P22: View cover
A23: 17 | B23: God of War Ragnarök | C23: Core | D23: 2022 | E23: Santa Monica Studio / Sony | F23: Action-Adventure | G23: 94 | H23: 94 | I23: 10 | J23: 10 | K23: 90 | L23: =IF(COUNT(G23:K23)=0,"",(SUM(G23:H23,K23)+10*SUM(I23:J23))/COUNT(G23:K23)) -> 95.6 | M23: 9.5151515 | O23: Refined sequel that expands the 2018 formula while delivering some of the strongest modern blockbuster combat. | P23: View cover
A24: 18 | B24: The Last of Us Part II | C24: Core | D24: 2020 | E24: Naughty Dog / Sony | F24: Action-Adventure | G24: 93 | J24: 8 | L24: =IF(COUNT(G24:K24)=0,"",(SUM(G24:H24,K24)+10*SUM(I24:J24))/COUNT(G24:K24)) -> 86.5 | M24: 9.4848485 | O24: Bold sequel with elite production, combat depth and unusually ambitious storytelling. | P24: View cover
A25: 19 | B25: Grand Theft Auto: San Andreas | C25: Core | D25: 2004 | E25: Rockstar North / Rockstar | F25: Open-world / Action-Adventure | G25: 95 | J25: 9.6 | L25: =IF(COUNT(G25:K25)=0,"",(SUM(G25:H25,K25)+10*SUM(I25:J25))/COUNT(G25:K25)) -> 95.5 | M25: 9.4545455 | O25: An enormous cultural landmark and one of the strongest examples of early 3D open-world freedom. | P25: View cover
A26: 20 | B26: Mass Effect 3 | C26: Core | D26: 2012 | E26: BioWare / EA | F26: Action RPG / Sci-Fi | G26: 93 | H26: 89 | I26: 9.5 | J26: 9.5 | K26: 90 | L26: =IF(COUNT(G26:K26)=0,"",(SUM(G26:H26,K26)+10*SUM(I26:J26))/COUNT(G26:K26)) -> 92.4 | M26: 9.4242424 | O26: Excellent RPG systems, companions and galaxy-scale storytelling despite a divisive finale. | P26: View cover
A27: 21 | B27: Fallout 3 | C27: Core | D27: 2008 | E27: Bethesda Game Studios | F27: Open-world RPG | G27: 93 | H27: 91 | I27: 9.6 | J27: 9 | K27: 92 | L27: =IF(COUNT(G27:K27)=0,"",(SUM(G27:H27,K27)+10*SUM(I27:J27))/COUNT(G27:K27)) -> 92.4 | M27: 9.3939394 | O27: A foundational modern open-world RPG with exploration, questing and atmosphere still worth experiencing. | P27: View cover
A28: 22 | B28: Baldur's Gate II: Shadows of Amn | C28: Core | D28: 2000 | E28: BioWare / Interplay | F28: CRPG / RPG | G28: 95 | J28: 9.6 | L28: =IF(COUNT(G28:K28)=0,"",(SUM(G28:H28,K28)+10*SUM(I28:J28))/COUNT(G28:K28)) -> 95.5 | M28: 9.4 | N28: (AI – not played) | O28: One of the foundational large-scale RPGs; less modern-looking, but massively important to the genre. | P28: View cover
A29: 23 | B29: Halo 3 | C29: Core | D29: 2007 | E29: Bungie / Microsoft | F29: FPS | G29: 94 | J29: 9.5 | L29: =IF(COUNT(G29:K29)=0,"",(SUM(G29:H29,K29)+10*SUM(I29:J29))/COUNT(G29:K29)) -> 94.5 | M29: 9.3333333 | O29: One of the defining console FPS campaigns and a major multiplayer-era blockbuster. | P29: View cover
A30: 24 | B30: Portal 2 | C30: Core | D30: 2011 | E30: Valve | F30: Puzzle / Adventure | G30: 95 | H30: 95 | I30: 10 | J30: 10 | K30: 94 | L30: =IF(COUNT(G30:K30)=0,"",(SUM(G30:H30,K30)+10*SUM(I30:J30))/COUNT(G30:K30)) -> 96.8 | M30: 9.3 | N30: (AI – not played) | O30: One of the strongest puzzle/adventure productions ever released by a major studio. | P30: View cover
A31: 25 | B31: Half-Life 2 | C31: Core | D31: 2004 | E31: Valve | F31: FPS / Action | G31: 96 | H31: 96 | I31: 9.7 | J31: 9.2 | K31: 96 | L31: =IF(COUNT(G31:K31)=0,"",(SUM(G31:H31,K31)+10*SUM(I31:J31))/COUNT(G31:K31)) -> 95.4 | M31: 9.2727273 | O31: A transformative FPS that reshaped physics, environmental storytelling and immersive level design. | P31: View cover
A32: 26 | B32: Cyberpunk 2077 | C32: Core | D32: 2020 | E32: CD Projekt Red | F32: Open-world RPG | G32: 86 | H32: 86 | I32: 9 | J32: 7 | K32: 78 | L32: =IF(COUNT(G32:K32)=0,"",(SUM(G32:H32,K32)+10*SUM(I32:J32))/COUNT(G32:K32)) -> 82 | M32: 9.2424242 | O32: An ambitious, visually striking RPG whose post-launch evolution is important to its legacy. | P32: View cover
A33: 27 | B33: Resident Evil 4 | C33: Core | D33: 2023 | E33: Capcom | F33: Survival Horror / Action | G33: 93 | H33: 91 | I33: 10 | J33: 10 | K33: 80 | L33: =IF(COUNT(G33:K33)=0,"",(SUM(G33:H33,K33)+10*SUM(I33:J33))/COUNT(G33:K33)) -> 92.8 | M33: 9.2121212 | O33: A benchmark survival-horror remake: masterful pacing, encounter design and combat that sharpen an all-time classic. | P33: View cover
A34: 28 | B34: Alan Wake 2 | C34: Core | D34: 2023 | E34: Remedy / Epic Games | F34: Survival Horror / Action | G34: 89 | H34: 89 | I34: 9 | J34: 9 | K34: 88 | L34: =IF(COUNT(G34:K34)=0,"",(SUM(G34:H34,K34)+10*SUM(I34:J34))/COUNT(G34:K34)) -> 89.2 | M34: 9.2 | N34: (AI – not played) | O34: A landmark modern horror production with exceptional audiovisual direction and narrative ambition. | P34: View cover
A35: 29 | B35: Control | C35: Core | D35: 2019 | E35: Remedy / 505 Games | F35: Action-Adventure | G35: 85 | H35: 82 | I35: 8.8 | J35: 8 | K35: 88 | L35: =IF(COUNT(G35:K35)=0,"",(SUM(G35:H35,K35)+10*SUM(I35:J35))/COUNT(G35:K35)) -> 84.6 | M35: 9.1515152 | O35: Distinctive AAA supernatural action with exceptional atmosphere, art direction and telekinetic combat. | P35: View cover
A36: 30 | B36: Star Wars: Knights of the Old Republic | C36: Core | D36: 2003 | E36: BioWare / LucasArts | F36: RPG | G36: 94 | H36: 94 | I36: 9.2 | J36: 9.1 | K36: 92 | L36: =IF(COUNT(G36:K36)=0,"",(SUM(G36:H36,K36)+10*SUM(I36:J36))/COUNT(G36:K36)) -> 92.6 | M36: 9.1 | N36: (AI – not played) | O36: A landmark licensed RPG with strong writing, choice and world-building. | P36: View cover
A37: 31 | B37: Metal Gear Solid 3: Snake Eater | C37: Core | D37: 2004 | E37: Konami | F37: Action / Stealth | G37: 91 | J37: 9 | L37: =IF(COUNT(G37:K37)=0,"",(SUM(G37:H37,K37)+10*SUM(I37:J37))/COUNT(G37:K37)) -> 90.5 | M37: 9.0909091 | O37: A landmark stealth blockbuster with exceptional survival mechanics and storytelling. | P37: View cover
A38: 32 | B38: Call of Duty 4: Modern Warfare | C38: Core | D38: 2007 | E38: Infinity Ward / Activision | F38: FPS | G38: 94 | H38: 92 | I38: 9.4 | J38: 9 | L38: =IF(COUNT(G38:K38)=0,"",(SUM(G38:H38,K38)+10*SUM(I38:J38))/COUNT(G38:K38)) -> 92.5 | M38: 9.0606061 | O38: A defining AAA shooter whose campaign, multiplayer and presentation changed the mainstream FPS. | P38: View cover
A39: 33 | B39: Assassin's Creed IV: Black Flag | C39: Core | D39: 2013 | E39: Ubisoft Montreal / Ubisoft | F39: Open-world Action-Adventure | G39: 88 | H39: 84 | I39: 9 | J39: 9 | K39: 86 | L39: =IF(COUNT(G39:K39)=0,"",(SUM(G39:H39,K39)+10*SUM(I39:J39))/COUNT(G39:K39)) -> 87.6 | M39: 9.030303 | O39: Combines Assassin's Creed with a highly memorable open-world naval sandbox. | P39: View cover
A40: 34 | B40: Dishonored | C40: Core | D40: 2012 | E40: Arkane / Bethesda | F40: Immersive Sim / Action | G40: 88 | H40: 88 | I40: 9.2 | J40: 9 | K40: 88 | L40: =IF(COUNT(G40:K40)=0,"",(SUM(G40:H40,K40)+10*SUM(I40:J40))/COUNT(G40:K40)) -> 89.2 | M40: 9 | N40: (AI – not played) | O40: A landmark modern immersive sim with excellent level design and player-driven approaches. | P40: View cover
A41: 35 | B41: The Elder Scrolls IV: Oblivion | C41: Core | D41: 2006 | E41: Bethesda Game Studios | F41: Open-world RPG | G41: 94 | H41: 94 | I41: 9.3 | J41: 9.5 | K41: 92 | L41: =IF(COUNT(G41:K41)=0,"",(SUM(G41:H41,K41)+10*SUM(I41:J41))/COUNT(G41:K41)) -> 93.6 | M41: 8.969697 | O41: One of the key early open-world RPGs and a direct ancestor to Skyrim. | P41: View cover
...

Sheet Chronology
A1: A CHRONOLOGY OF THE COLLECTION
A2: All 100 entries, ordered by the source year, then curated rank. These are source years—not independently verified release dates.
A4: ← Start Here | C4: The 100 → | F4: How to read →
A5: Ranks stay curated. Critics and Leul's preserved original ratings look up The 100 by rank; links remain correct after sorting.
A6: Year | B6: Rank | C6: Game | D6: Tier | E6: Publisher / Studio | F6: Genre | G6: Critic average /100 | H6: Leul's original rating /10 | I6: Source note | J6: Entry
A7: 2000 | B7: 22 | C7: Baldur's Gate II: Shadows of Amn | D7: Core | E7: BioWare / Interplay | F7: CRPG / RPG | G7: =IFERROR(INDEX('The 100'!$L$7:$L$106,MATCH(B7,'The 100'!$A$7:$A$106,0)),"") -> 95.5 | H7: =IFERROR(INDEX('The 100'!$M$7:$M$106,MATCH(B7,'The 100'!$A$7:$A$106,0)),"") -> 9.4 | I7: (AI – not played) | J7: =HYPERLINK("#'The 100'!B"&(MATCH(B7,'The 100'!$A$7:$A$106,0)+6),"Open entry") -> Open entry
A8: 2000 | B8: 60 | C8: Diablo II | D8: Essential | E8: Blizzard | F8: Action RPG | G8: =IFERROR(INDEX('The 100'!$L$7:$L$106,MATCH(B8,'The 100'!$A$7:$A$106,0)),"") -> 89.333333 | H8: =IFERROR(INDEX('The 100'!$M$7:$M$106,MATCH(B8,'The 100'!$A$7:$A$106,0)),"") -> 8.2121212 | J8: =HYPERLINK("#'The 100'!B"&(MATCH(B8,'The 100'!$A$7:$A$106,0)+6),"Open entry") -> Open entry
A9: 2002 | B9: 46 | C9: Grand Theft Auto: Vice City | D9: Core | E9: Rockstar North / Rockstar | F9: Open-world / Action-Adventure | G9: =IFERROR(INDEX('The 100'!$L$7:$L$106,MATCH(B9,'The 100'!$A$7:$A$106,0)),"") -> 95.666667 | H9: =IFERROR(INDEX('The 100'!$M$7:$M$106,MATCH(B9,'The 100'!$A$7:$A$106,0)),"") -> 8.6363636 | J9: =HYPERLINK("#'The 100'!B"&(MATCH(B9,'The 100'!$A$7:$A$106,0)+6),"Open entry") -> Open entry
A10: 2002 | B10: 64 | C10: Warcraft III: Reign of Chaos | D10: Essential | E10: Blizzard | F10: RTS | G10: =IFERROR(INDEX('The 100'!$L$7:$L$106,MATCH(B10,'The 100'!$A$7:$A$106,0)),"") -> 92.333333 | H10: =IFERROR(INDEX('The 100'!$M$7:$M$106,MATCH(B10,'The 100'!$A$7:$A$106,0)),"") -> 8.0909091 | J10: =HYPERLINK("#'The 100'!B"&(MATCH(B10,'The 100'!$A$7:$A$106,0)+6),"Open entry") -> Open entry
A11: 2003 | B11: 30 | C11: Star Wars: Knights of the Old Republic | D11: Core | E11: BioWare / LucasArts | F11: RPG | G11: =IFERROR(INDEX('The 100'!$L$7:$L$106,MATCH(B11,'The 100'!$A$7:$A$106,0)),"") -> 92.6 | H11: =IFERROR(INDEX('The 100'!$M$7:$M$106,MATCH(B11,'The 100'!$A$7:$A$106,0)),"") -> 9.1 | I11: (AI – not played) | J11: =HYPERLINK("#'The 100'!B"&(MATCH(B11,'The 100'!$A$7:$A$106,0)+6),"Open entry") -> Open entry
A12: 2004 | B12: 19 | C12: Grand Theft Auto: San Andreas | D12: Core | E12: Rockstar North / Rockstar | F12: Open-world / Action-Adventure | G12: =IFERROR(INDEX('The 100'!$L$7:$L$106,MATCH(B12,'The 100'!$A$7:$A$106,0)),"") -> 95.5 | H12: =IFERROR(INDEX('The 100'!$M$7:$M$106,MATCH(B12,'The 100'!$A$7:$A$106,0)),"") -> 9.4545455 | J12: =HYPERLINK("#'The 100'!B"&(MATCH(B12,'The 100'!$A$7:$A$106,0)+6),"Open entry") -> Open entry
A13: 2004 | B13: 25 | C13: Half-Life 2 | D13: Core | E13: Valve | F13: FPS / Action | G13: =IFERROR(INDEX('The 100'!$L$7:$L$106,MATCH(B13,'The 100'!$A$7:$A$106,0)),"") -> 95.4 | H13: =IFERROR(INDEX('The 100'!$M$7:$M$106,MATCH(B13,'The 100'!$A$7:$A$106,0)),"") -> 9.2727273 | J13: =HYPERLINK("#'The 100'!B"&(MATCH(B13,'The 100'!$A$7:$A$106,0)+6),"Open entry") -> Open entry
A14: 2004 | B14: 31 | C14: Metal Gear Solid 3: Snake Eater | D14: Core | E14: Konami | F14: Action / Stealth | G14: =IFERROR(INDEX('The 100'!$L$7:$L$106,MATCH(B14,'The 100'!$A$7:$A$106,0)),"") -> 90.5 | H14: =IFERROR(INDEX('The 100'!$M$7:$M$106,MATCH(B14,'The 100'!$A$7:$A$106,0)),"") -> 9.0909091 | J14: =HYPERLINK("#'The 100'!B"&(MATCH(B14,'The 100'!$A$7:$A$106,0)+6),"Open entry") -> Open entry
A15: 2004 | B15: 62 | C15: World of Warcraft | D15: Essential | E15: Blizzard | F15: MMORPG | G15: =IFERROR(INDEX('The 100'!$L$7:$L$106,MATCH(B15,'The 100'!$A$7:$A$106,0)),"") -> 92.666667 | H15: =IFERROR(INDEX('The 100'!$M$7:$M$106,MATCH(B15,'The 100'!$A$7:$A$106,0)),"") -> 8.1515152 | J15: =HYPERLINK("#'The 100'!B"&(MATCH(B15,'The 100'!$A$7:$A$106,0)+6),"Open entry") -> Open entry
A16: 2005 | B16: 58 | C16: Kingdom Hearts II | D16: Essential | E16: Square Enix | F16: Action RPG | G16: =IFERROR(INDEX('The 100'!$L$7:$L$106,MATCH(B16,'The 100'!$A$7:$A$106,0)),"") -> 89 | H16: =IFERROR(INDEX('The 100'!$M$7:$M$106,MATCH(B16,'The 100'!$A$7:$A$106,0)),"") -> 8.2727273 | J16: =HYPERLINK("#'The 100'!B"&(MATCH(B16,'The 100'!$A$7:$A$106,0)+6),"Open entry") -> Open entry
A17: 2006 | B17: 35 | C17: The Elder Scrolls IV: Oblivion | D17: Core | E17: Bethesda Game Studios | F17: Open-world RPG | G17: =IFERROR(INDEX('The 100'!$L$7:$L$106,MATCH(B17,'The 100'!$A$7:$A$106,0)),"") -> 93.6 | H17: =IFERROR(INDEX('The 100'!$M$7:$M$106,MATCH(B17,'The 100'!$A$7:$A$106,0)),"") -> 8.969697 | J17: =HYPERLINK("#'The 100'!B"&(MATCH(B17,'The 100'!$A$7:$A$106,0)+6),"Open entry") -> Open entry
A18: 2007 | B18: 9 | C18: BioShock | D18: Core | E18: 2K / Irrational Games | F18: FPS / Narrative | G18: =IFERROR(INDEX('The 100'!$L$7:$L$106,MATCH(B18,'The 100'!$A$7:$A$106,0)),"") -> 94 | H18: =IFERROR(INDEX('The 100'!$M$7:$M$106,MATCH(B18,'The 100'!$A$7:$A$106,0)),"") -> 9.7575758 | J18: =HYPERLINK("#'The 100'!B"&(MATCH(B18,'The 100'!$A$7:$A$106,0)+6),"Open entry") -> Open entry
A19: 2007 | B19: 10 | C19: Mass Effect | D19: Core | E19: BioWare / EA | F19: Action RPG / Sci-Fi | G19: =IFERROR(INDEX('The 100'!$L$7:$L$106,MATCH(B19,'The 100'!$A$7:$A$106,0)),"") -> 87 | H19: =IFERROR(INDEX('The 100'!$M$7:$M$106,MATCH(B19,'The 100'!$A$7:$A$106,0)),"") -> 9.7272727 | J19: =HYPERLINK("#'The 100'!B"&(MATCH(B19,'The 100'!$A$7:$A$106,0)+6),"Open entry") -> Open entry
A20: 2007 | B20: 23 | C20: Halo 3 | D20: Core | E20: Bungie / Microsoft | F20: FPS | G20: =IFERROR(INDEX('The 100'!$L$7:$L$106,MATCH(B20,'The 100'!$A$7:$A$106,0)),"") -> 94.5 | H20: =IFERROR(INDEX('The 100'!$M$7:$M$106,MATCH(B20,'The 100'!$A$7:$A$106,0)),"") -> 9.3333333 | J20: =HYPERLINK("#'The 100'!B"&(MATCH(B20,'The 100'!$A$7:$A$106,0)+6),"Open entry") -> Open entry
A21: 2007 | B21: 32 | C21: Call of Duty 4: Modern Warfare | D21: Core | E21: Infinity Ward / Activision | F21: FPS | G21: =IFERROR(INDEX('The 100'!$L$7:$L$106,MATCH(B21,'The 100'!$A$7:$A$106,0)),"") -> 92.5 | H21: =IFERROR(INDEX('The 100'!$M$7:$M$106,MATCH(B21,'The 100'!$A$7:$A$106,0)),"") -> 9.0606061 | J21: =HYPERLINK("#'The 100'!B"&(MATCH(B21,'The 100'!$A$7:$A$106,0)+6),"Open entry") -> Open entry
A22: 2008 | B22: 7 | C22: Grand Theft Auto IV | D22: Core | E22: Rockstar Games | F22: Open-world / Action-Adventure | G22: =IFERROR(INDEX('The 100'!$L$7:$L$106,MATCH(B22,'The 100'!$A$7:$A$106,0)),"") -> 96 | H22: =IFERROR(INDEX('The 100'!$M$7:$M$106,MATCH(B22,'The 100'!$A$7:$A$106,0)),"") -> 9.8 | J22: =HYPERLINK("#'The 100'!B"&(MATCH(B22,'The 100'!$A$7:$A$106,0)+6),"Open entry") -> Open entry
A23: 2008 | B23: 21 | C23: Fallout 3 | D23: Core | E23: Bethesda Game Studios | F23: Open-world RPG | G23: =IFERROR(INDEX('The 100'!$L$7:$L$106,MATCH(B23,'The 100'!$A$7:$A$106,0)),"") -> 92.4 | H23: =IFERROR(INDEX('The 100'!$M$7:$M$106,MATCH(B23,'The 100'!$A$7:$A$106,0)),"") -> 9.3939394 | J23: =HYPERLINK("#'The 100'!B"&(MATCH(B23,'The 100'!$A$7:$A$106,0)+6),"Open entry") -> Open entry
... A30: 2010 | B30: 67 | C30: Call of Duty: Black Ops | D30: Essential | E30: Treyarch / Activision | F30: FPS | G30: =IFERROR(INDEX('The 100'!$L$7:$L$106,MATCH(B30,'The 100'!$A$7:$A$106,0)),"") -> 87.25 | H30: =IFERROR(INDEX('The 100'!$M$7:$M$106,MATCH(B30,'The 100'!$A$7:$A$106,0)),"") -> 8 | J30: =HYPERLINK("#'The 100'!B"&(MATCH(B30,'The 100'!$A$7:$A$106,0)+6),"Open entry") -> Open entry
A31: 2011 | B31: 11 | C31: The Elder Scrolls V: Skyrim | D31: Core | E31: Bethesda Game Studios | F31: Open-world RPG | G31: =IFERROR(INDEX('The 100'!$L$7:$L$106,MATCH(B31,'The 100'!$A$7:$A$106,0)),"") -> 94.8 | H31: =IFERROR(INDEX('The 100'!$M$7:$M$106,MATCH(B31,'The 100'!$A$7:$A$106,0)),"") -> 9.7 | I31: (AI – not played) | J31: =HYPERLINK("#'The 100'!B"&(MATCH(B31,'The 100'!$A$7:$A$106,0)+6),"Open entry") -> Open entry
A32: 2011 | B32: 14 | C32: Batman: Arkham City | D32: Core | E32: Rocksteady / WB Games | F32: Action-Adventure | G32: =IFERROR(INDEX('The 100'!$L$7:$L$106,MATCH(B32,'The 100'!$A$7:$A$106,0)),"") -> 93.4 | H32: =IFERROR(INDEX('The 100'!$M$7:$M$106,MATCH(B32,'The 100'!$A$7:$A$106,0)),"") -> 9.6060606 | J32: =HYPERLINK("#'The 100'!B"&(MATCH(B32,'The 100'!$A$7:$A$106,0)+6),"Open entry") -> Open entry
A33: 2011 | B33: 24 | C33: Portal 2 | D33: Core | E33: Valve | F33: Puzzle / Adventure | G33: =IFERROR(INDEX('The 100'!$L$7:$L$106,MATCH(B33,'The 100'!$A$7:$A$106,0)),"") -> 96.8 | H33: =IFERROR(INDEX('The 100'!$M$7:$M$106,MATCH(B33,'The 100'!$A$7:$A$106,0)),"") -> 9.3 | I33: (AI – not played) | J33: =HYPERLINK("#'The 100'!B"&(MATCH(B33,'The 100'!$A$7:$A$106,0)+6),"Open entry") -> Open entry
A34: 2011 | B34: 70 | C34: Battlefield 3 | D34: Essential | E34: DICE / EA | F34: FPS | G34: =IFERROR(INDEX('The 100'!$L$7:$L$106,MATCH(B34,'The 100'!$A$7:$A$106,0)),"") -> 88 | H34: =IFERROR(INDEX('The 100'!$M$7:$M$106,MATCH(B34,'The 100'!$A$7:$A$106,0)),"") -> 7.9090909 | J34: =HYPERLINK("#'The 100'!B"&(MATCH(B34,'The 100'!$A$7:$A$106,0)+6),"Open entry") -> Open entry
A35: 2011 | B35: 100 | C35: L.A. Noire | D35: Essential | E35: Team Bondi / Rockstar Games | F35: Action-Adventure / Detective | G35: =IFERROR(INDEX('The 100'!$L$7:$L$106,MATCH(B35,'The 100'!$A$7:$A$106,0)),"") -> 81.6 | H35: =IFERROR(INDEX('The 100'!$M$7:$M$106,MATCH(B35,'The 100'!$A$7:$A$106,0)),"") -> 7 | J35: =HYPERLINK("#'The 100'!B"&(MATCH(B35,'The 100'!$A$7:$A$106,0)+6),"Open entry") -> Open entry
A36: 2012 | B36: 20 | C36: Mass Effect 3 | D36: Core | E36: BioWare / EA | F36: Action RPG / Sci-Fi | G36: =IFERROR(INDEX('The 100'!$L$7:$L$106,MATCH(B36,'The 100'!$A$7:$A$106,0)),"") -> 92.4 | H36: =IFERROR(INDEX('The 100'!$M$7:$M$106,MATCH(B36,'The 100'!$A$7:$A$106,0)),"") -> 9.4242424 | J36: =HYPERLINK("#'The 100'!B"&(MATCH(B36,'The 100'!$A$7:$A$106,0)+6),"Open entry") -> Open entry
A37: 2012 | B37: 34 | C37: Dishonored | D37: Core | E37: Arkane / Bethesda | F37: Immersive Sim / Action | G37: =IFERROR(INDEX('The 100'!$L$7:$L$106,MATCH(B37,'The 100'!$A$7:$A$106,0)),"") -> 89.2 | H37: =IFERROR(INDEX('The 100'!$M$7:$M$106,MATCH(B37,'The 100'!$A$7:$A$106,0)),"") -> 9 | I37: (AI – not played) | J37: =HYPERLINK("#'The 100'!B"&(MATCH(B37,'The 100'!$A$7:$A$106,0)+6),"Open entry") -> Open entry
A38: 2012 | B38: 68 | C38: Call of Duty: Black Ops II | D38: Essential | E38: Treyarch / Activision | F38: FPS | G38: =IFERROR(INDEX('The 100'!$L$7:$L$106,MATCH(B38,'The 100'!$A$7:$A$106,0)),"") -> 85.8 | H38: =IFERROR(INDEX('The 100'!$M$7:$M$106,MATCH(B38,'The 100'!$A$7:$A$106,0)),"") -> 7.969697 | J38: =HYPERLINK("#'The 100'!B"&(MATCH(B38,'The 100'!$A$7:$A$106,0)+6),"Open entry") -> Open entry
A39: 2012 | B39: 95 | C39: Sleeping Dogs | D39: Essential | E39: United Front Games / Square Enix | F39: Open-world Action | G39: =IFERROR(INDEX('The 100'!$L$7:$L$106,MATCH(B39,'The 100'!$A$7:$A$106,0)),"") -> 81.6 | H39: =IFERROR(INDEX('The 100'!$M$7:$M$106,MATCH(B39,'The 100'!$A$7:$A$106,0)),"") -> 7.1515152 | J39: =HYPERLINK("#'The 100'!B"&(MATCH(B39,'The 100'!$A$7:$A$106,0)+6),"Open entry") -> Open entry
A40: 2012 | B40: 97 | C40: Max Payne 3 | D40: Essential | E40: Rockstar Studios / Rockstar Games | F40: Third-person Shooter / Action | G40: =IFERROR(INDEX('The 100'!$L$7:$L$106,MATCH(B40,'The 100'!$A$7:$A$106,0)),"") -> 88.4 | H40: =IFERROR(INDEX('The 100'!$M$7:$M$106,MATCH(B40,'The 100'!$A$7:$A$106,0)),"") -> 7.0909091 | J40: =HYPERLINK("#'The 100'!B"&(MATCH(B40,'The 100'!$A$7:$A$106,0)+6),"Open entry") -> Open entry
A41: 2013 | B41: 5 | C41: The Last of Us | D41: Core | E41: Naughty Dog / Sony | F41: Action-Adventure / Survival | G41: =IFERROR(INDEX('The 100'!$L$7:$L$106,MATCH(B41,'The 100'!$A$7:$A$106,0)),"") -> 91.666667 | H41: =IFERROR(INDEX('The 100'!$M$7:$M$106,MATCH(B41,'The 100'!$A$7:$A$106,0)),"") -> 9.8787879 | J41: =HYPERLINK("#'The 100'!B"&(MATCH(B41,'The 100'!$A$7:$A$106,0)+6),"Open entry") -> Open entry
A42: 2013 | B42: 6 | C42: Grand Theft Auto V | D42: Core | E42: Rockstar Games | F42: Open-world / Action-Adventure | G42: =IFERROR(INDEX('The 100'!$L$7:$L$106,MATCH(B42,'The 100'!$A$7:$A$106,0)),"") -> 95.2 | H42: =IFERROR(INDEX('The 100'!$M$7:$M$106,MATCH(B42,'The 100'!$A$7:$A$106,0)),"") -> 9.8484848 | J42: =HYPERLINK("#'The 100'!B"&(MATCH(B42,'The 100'!$A$7:$A$106,0)+6),"Open entry") -> Open entry
A43: 2013 | B43: 33 | C43: Assassin's Creed IV: Black Flag | D43: Core | E43: Ubisoft Montreal / Ubisoft | F43: Open-world Action-Adventure | G43: =IFERROR(INDEX('The 100'!$L$7:$L$106,MATCH(B43,'The 100'!$A$7:$A$106,0)),"") -> 87.6 | H43: =IFERROR(INDEX('The 100'!$M$7:$M$106,MATCH(B43,'The 100'!$A$7:$A$106,0)),"") -> 9.030303 | J43: =HYPERLINK("#'The 100'!B"&(MATCH(B43,'The 100'!$A$7:$A$106,0)+6),"Open entry") -> Open entry
A44: 2013 | B44: 71 | C44: Battlefield 4 | D44: Essential | E44: DICE / EA | F44: FPS | G44: =IFERROR(INDEX('The 100'!$L$7:$L$106,MATCH(B44,'The 100'!$A$7:$A$106,0)),"") -> 82.5 | H44: =IFERROR(INDEX('The 100'!$M$7:$M$106,MATCH(B44,'The 100'!$A$7:$A$106,0)),"") -> 7.8787879 | J44: =HYPERLINK("#'The 100'!B"&(MATCH(B44,'The 100'!$A$7:$A$106,0)+6),"Open entry") -> Open entry
A45: 2013 | B45: 98 | C45: Tomb Raider | D45: Essential | E45: Crystal Dynamics / Square Enix | F45: Action-Adventure | G45: =IFERROR(INDEX('The 100'!$L$7:$L$106,MATCH(B45,'The 100'!$A$7:$A$106,0)),"") -> 86.4 | H45: =IFERROR(INDEX('The 100'!$M$7:$M$106,MATCH(B45,'The 100'!$A$7:$A$106,0)),"") -> 7.0606061 | J45: =HYPERLINK("#'The 100'!B"&(MATCH(B45,'The 100'!$A$7:$A$106,0)+6),"Open entry") -> Open entry
A46: 2014 | B46: 37 | C46: Far Cry 4 | D46: Core | E46: Ubisoft Montreal / Ubisoft | F46: Open-world FPS | G46: =IFERROR(INDEX('The 100'!$L$7:$L$106,MATCH(B46,'The 100'!$A$7:$A$106,0)),"") -> 82 | H46: =IFERROR(INDEX('The 100'!$M$7:$M$106,MATCH(B46,'The 100'!$A$7:$A$106,0)),"") -> 8.9090909 | J46: =HYPERLINK("#'The 100'!B"&(MATCH(B46,'The 100'!$A$7:$A$106,0)+6),"Open entry") -> Open entry
A47: 2014 | B47: 38 | C47: Dragon Age: Inquisition | D47: Core | E47: BioWare / EA | F47: Open-world RPG | G47: =IFERROR(INDEX('The 100'!$L$7:$L$106,MATCH(B47,'The 100'!$A$7:$A$106,0)),"") -> 87.8 | H47: =IFERROR(INDEX('The 100'!$M$7:$M$106,MATCH(B47,'The 100'!$A$7:$A$106,0)),"") -> 8.9 | I47: (AI – not played) | J47: =HYPERLINK("#'The 100'!B"&(MATCH(B47,'The 100'!$A$7:$A$106,0)+6),"Open entry") -> Open entry
...

Sheet Cover Gallery
A1: THE COVER GALLERY
A2: 100 supplied covers · curated order · nine larger Posters images preferred over duplicate thumbnails. Original image bytes are retained.
A4: ← Start Here | F4: The 100 → | K4: Artwork notes →
A5: Representative source artwork, not proof of platform availability or exact edition. Small originals may look soft. Rank 73 uses source art branded HITMAN III.
A7: 001 Red Dead Redemption 2 | F7: 002 Mass Effect 2 | K7: 003 The Witcher 3: Wild Hunt | P7: 004 God of War
A16: 2018 / Core | F16: 2010 / Core | K16: 2015 / Core | P16: 2018 / Core
A17: =HYPERLINK("#'The 100'!B"&(MATCH(1,'The 100'!$A$7:$A$106,0)+6),"View this entry →") -> View this entry → | F17: =HYPERLINK("#'The 100'!B"&(MATCH(2,'The 100'!$A$7:$A$106,0)+6),"View this entry →") -> View this entry → | K17: =HYPERLINK("#'The 100'!B"&(MATCH(3,'The 100'!$A$7:$A$106,0)+6),"View this entry →") -> View this entry → | P17: =HYPERLINK("#'The 100'!B"&(MATCH(4,'The 100'!$A$7:$A$106,0)+6),"View this entry →") -> View this entry →
A19: 005 The Last of Us | F19: 006 Grand Theft Auto V | K19: 007 Grand Theft Auto IV | P19: 008 Red Dead Redemption
A28: 2013 / Core | F28: 2013 / Core | K28: 2008 / Core | P28: 2010 / Core
A29: =HYPERLINK("#'The 100'!B"&(MATCH(5,'The 100'!$A$7:$A$106,0)+6),"View this entry →") -> View this entry → | F29: =HYPERLINK("#'The 100'!B"&(MATCH(6,'The 100'!$A$7:$A$106,0)+6),"View this entry →") -> View this entry → | K29: =HYPERLINK("#'The 100'!B"&(MATCH(7,'The 100'!$A$7:$A$106,0)+6),"View this entry →") -> View this entry → | P29: =HYPERLINK("#'The 100'!B"&(MATCH(8,'The 100'!$A$7:$A$106,0)+6),"View this entry →") -> View this entry →
A31: 009 BioShock | F31: 010 Mass Effect | K31: 011 The Elder Scrolls V: Skyrim | P31: 012 Baldur's Gate 3
A40: 2007 / Core | F40: 2007 / Core | K40: 2011 / Core | P40: 2023 / Core
A41: =HYPERLINK("#'The 100'!B"&(MATCH(9,'The 100'!$A$7:$A$106,0)+6),"View this entry →") -> View this entry → | F41: =HYPERLINK("#'The 100'!B"&(MATCH(10,'The 100'!$A$7:$A$106,0)+6),"View this entry →") -> View this entry → | K41: =HYPERLINK("#'The 100'!B"&(MATCH(11,'The 100'!$A$7:$A$106,0)+6),"View this entry →") -> View this entry → | P41: =HYPERLINK("#'The 100'!B"&(MATCH(12,'The 100'!$A$7:$A$106,0)+6),"View this entry →") -> View this entry →
A43: 013 Clair Obscur: Expedition 33 | F43: 014 Batman: Arkham City | K43: 015 Elden Ring | P43: 016 Uncharted 4: A Thief's End
A52: 2025 / Core | F52: 2011 / Core | K52: 2022 / Core | P52: 2016 / Core
A53: =HYPERLINK("#'The 100'!B"&(MATCH(13,'The 100'!$A$7:$A$106,0)+6),"View this entry →") -> View this entry → | F53: =HYPERLINK("#'The 100'!B"&(MATCH(14,'The 100'!$A$7:$A$106,0)+6),"View this entry →") -> View this entry → | K53: =HYPERLINK("#'The 100'!B"&(MATCH(15,'The 100'!$A$7:$A$106,0)+6),"View this entry →") -> View this entry → | P53: =HYPERLINK("#'The 100'!B"&(MATCH(16,'The 100'!$A$7:$A$106,0)+6),"View this entry →") -> View this entry →
A55: 017 God of War Ragnarök | F55: 018 The Last of Us Part II | K55: 019 Grand Theft Auto: San Andreas | P55: 020 Mass Effect 3
A64: 2022 / Core | F64: 2020 / Core | K64: 2004 / Core | P64: 2012 / Core
A65: =HYPERLINK("#'The 100'!B"&(MATCH(17,'The 100'!$A$7:$A$106,0)+6),"View this entry →") -> View this entry → | F65: =HYPERLINK("#'The 100'!B"&(MATCH(18,'The 100'!$A$7:$A$106,0)+6),"View this entry →") -> View this entry → | K65: =HYPERLINK("#'The 100'!B"&(MATCH(19,'The 100'!$A$7:$A$106,0)+6),"View this entry →") -> View this entry → | P65: =HYPERLINK("#'The 100'!B"&(MATCH(20,'The 100'!$A$7:$A$106,0)+6),"View this entry →") -> View this entry →
A67: 021 Fallout 3 | F67: 022 Baldur's Gate II: Shadows of Amn | K67: 023 Halo 3 | P67: 024 Portal 2
A76: 2008 / Core | F76: 2000 / Core | K76: 2007 / Core | P76: 2011 / Core
A77: =HYPERLINK("#'The 100'!B"&(MATCH(21,'The 100'!$A$7:$A$106,0)+6),"View this entry →") -> View this entry → | F77: =HYPERLINK("#'The 100'!B"&(MATCH(22,'The 100'!$A$7:$A$106,0)+6),"View this entry →") -> View this entry → | K77: =HYPERLINK("#'The 100'!B"&(MATCH(23,'The 100'!$A$7:$A$106,0)+6),"View this entry →") -> View this entry → | P77: =HYPERLINK("#'The 100'!B"&(MATCH(24,'The 100'!$A$7:$A$106,0)+6),"View this entry →") -> View this entry →
A79: 025 Half-Life 2 | F79: 026 Cyberpunk 2077 | K79: 027 Resident Evil 4 | P79: 028 Alan Wake 2
A88: 2004 / Core | F88: 2020 / Core | K88: 2023 / Core | P88: 2023 / Core
A89: =HYPERLINK("#'The 100'!B"&(MATCH(25,'The 100'!$A$7:$A$106,0)+6),"View this entry →") -> View this entry → | F89: =HYPERLINK("#'The 100'!B"&(MATCH(26,'The 100'!$A$7:$A$106,0)+6),"View this entry →") -> View this entry → | K89: =HYPERLINK("#'The 100'!B"&(MATCH(27,'The 100'!$A$7:$A$106,0)+6),"View this entry →") -> View this entry → | P89: =HYPERLINK("#'The 100'!B"&(MATCH(28,'The 100'!$A$7:$A$106,0)+6),"View this entry →") -> View this entry →
A91: 029 Control | F91: 030 Star Wars: Knights of the Old Republic | K91: 031 Metal Gear Solid 3: Snake Eater | P91: 032 Call of Duty 4: Modern Warfare
A100: 2019 / Core | F100: 2003 / Core | K100: 2004 / Core | P100: 2007 / Core
A101: =HYPERLINK("#'The 100'!B"&(MATCH(29,'The 100'!$A$7:$A$106,0)+6),"View this entry →") -> View this entry → | F101: =HYPERLINK("#'The 100'!B"&(MATCH(30,'The 100'!$A$7:$A$106,0)+6),"View this entry →") -> View this entry → | K101: =HYPERLINK("#'The 100'!B"&(MATCH(31,'The 100'!$A$7:$A$106,0)+6),"View this entry →") -> View this entry → | P101: =HYPERLINK("#'The 100'!B"&(MATCH(32,'The 100'!$A$7:$A$106,0)+6),"View this entry →") -> View this entry →
A103: 033 Assassin's Creed IV: Black Flag | F103: 034 Dishonored | K103: 035 The Elder Scrolls IV: Oblivion | P103: 036 Halo: Reach
A112: 2013 / Core | F112: 2012 / Core | K112: 2006 / Core | P112: 2010 / Core
A113: =HYPERLINK("#'The 100'!B"&(MATCH(33,'The 100'!$A$7:$A$106,0)+6),"View this entry →") -> View this entry → | F113: =HYPERLINK("#'The 100'!B"&(MATCH(34,'The 100'!$A$7:$A$106,0)+6),"View this entry →") -> View this entry → | K113: =HYPERLINK("#'The 100'!B"&(MATCH(35,'The 100'!$A$7:$A$106,0)+6),"View this entry →") -> View this entry → | P113: =HYPERLINK("#'The 100'!B"&(MATCH(36,'The 100'!$A$7:$A$106,0)+6),"View this entry →") -> View this entry →
A115: 037 Far Cry 4 | F115: 038 Dragon Age: Inquisition | K115: 039 Metro Exodus | P115: 040 Resident Evil 2
A124: 2014 / Core | F124: 2014 / Core | K124: 2019 / Core | P124: 2019 / Core
A125: =HYPERLINK("#'The 100'!B"&(MATCH(37,'The 100'!$A$7:$A$106,0)+6),"View this entry →") -> View this entry → | F125: =HYPERLINK("#'The 100'!B"&(MATCH(38,'The 100'!$A$7:$A$106,0)+6),"View this entry →") -> View this entry → | K125: =HYPERLINK("#'The 100'!B"&(MATCH(39,'The 100'!$A$7:$A$106,0)+6),"View this entry →") -> View this entry → | P125: =HYPERLINK("#'The 100'!B"&(MATCH(40,'The 100'!$A$7:$A$106,0)+6),"View this entry →") -> View this entry →
A127: 041 Resident Evil Requiem | F127: 042 Titanfall 2 | K127: 043 Star Wars Battlefront II | P127: 044 Sekiro: Shadows Die Twice
A136: 2026 / Core | F136: 2016 / Core | K136: 2017 / Core | P136: 2019 / Core
A137: =HYPERLINK("#'The 100'!B"&(MATCH(41,'The 100'!$A$7:$A$106,0)+6),"View this entry →") -> View this entry → | F137: =HYPERLINK("#'The 100'!B"&(MATCH(42,'The 100'!$A$7:$A$106,0)+6),"View this entry →") -> View this entry → | K137: =HYPERLINK("#'The 100'!B"&(MATCH(43,'The 100'!$A$7:$A$106,0)+6),"View this entry →") -> View this entry → | P137: =HYPERLINK("#'The 100'!B"&(MATCH(44,'The 100'!$A$7:$A$106,0)+6),"View this entry →") -> View this entry →
A139: 045 Bloodborne | F139: 046 Grand Theft Auto: Vice City | K139: 047 Star Wars Jedi: Fallen Order | P139: 048 Horizon Zero Dawn
A148: 2015 / Core | F148: 2002 / Core | K148: 2019 / Core | P148: 2017 / Core
A149: =HYPERLINK("#'The 100'!B"&(MATCH(45,'The 100'!$A$7:$A$106,0)+6),"View this entry →") -> View this entry → | F149: =HYPERLINK("#'The 100'!B"&(MATCH(46,'The 100'!$A$7:$A$106,0)+6),"View this entry →") -> View this entry → | K149: =HYPERLINK("#'The 100'!B"&(MATCH(47,'The 100'!$A$7:$A$106,0)+6),"View this entry →") -> View this entry → | P149: =HYPERLINK("#'The 100'!B"&(MATCH(48,'The 100'!$A$7:$A$106,0)+6),"View this entry →") -> View this entry →
...

Sheet Methodology
A1: METHODOLOGY & PROVENANCE
A2: An honest guide to the collection, its numbers, its artwork, and its source.
A4: ← Start Here | E4: The 100 →
A7: 01 / SCOPE | D7: Mainstream AAA / blockbuster / major-publisher flagship games, plus a small number of AAA-caliber premium exceptions that clearly belong in an essential modern-gaming list. Nintendo excluded.
A12: 02 / RANKING | D12: Curated must-play ranking, not a raw Metacritic leaderboard. Signals in the source: Critical acclaim, lasting reputation, industry influence, cultural impact, design quality, production ambition and “must-play” status.
A17: 03 / TIERS | D17: Core = ranks 1–50. Essential = ranks 51–100. The division is editorial, not a score cutoff. No source title was added, removed, promoted or demoted.
A22: 04 / NATIVE SCALES | D22: Metacritic, Metacritic PC and PC Gamer use /100. IGN and GameSpot use /10. A blank means no numeric value was entered in the primary snapshot; it never means zero.
A27: 05 / CRITIC AVERAGE | D27: Normalize IGN and GameSpot by multiplying by 10; then average only numeric, available columns. Both Metacritic columns count separately when entered. This is not an average of independent publications and is not the ranking algorithm.
A32: 06 / LEUL'S ORIGINAL RATING | D32: The original column L is headed “my rating(based on rank)”. It contains Leul's own ratings, based on his curated ranking. The original cached values are copied exactly; rounded TEXT results remain rounded (for example The Witcher 3 = 9.9 and Grand Theft Auto IV = 9.8). No formula repairs or reconstructed curve replace those values. This is separate from critic averages and any visitor's private website rating.
A37: 07 / SOURCE NOTES | D37: Twelve author-rating cells contain “(AI – not played)”. Their numeric author rating and original note are both preserved. An absent source note does not establish play history. Historical author notes never set a visitor's Played/Completed state.
A42: 08 / WHAT IS VERIFIED | D42: The extraction, arithmetic, record count, source preservation, formula caches and image mapping were checked. Critic scores, game years, platform editions and release metadata were not independently reverified. No critic snapshot date is known.
A47: 09 / DATA PRESERVATION | D47: Game titles, studios, source years, genres, native critic entries and ranking rationales come from the primary sheet unchanged. Non-AAA premium exceptions already present in the source remain included. JSON genreTags only split the existing genre text at slash separators.
A52: 10 / FORMULAS | D52: The 100 recalculates critic averages from entered columns. Leul's original ratings are fixed copied numbers so recalculation cannot silently rewrite them. Chronology looks up both metrics by rank with matching initial caches. Sorting either table preserves associations. Formula mode is automatic; there are no macros or external workbook links.
A57: 11 / COVER PROVENANCE | D57: 109 original embedded images were found: 100 row thumbnails and nine larger gallery posters. For each game, the largest correctly anchored supplied image is reused without altering its bytes. All nine poster labels match exact primary titles. No artwork was fetched, invented or replaced.
A62: 12 / COVER LIMITATIONS | D62: The source is low resolution: 91 selected covers are 120 pixels high; nine are larger. Covers are representative editions and cannot establish platform availability. Rank 73 is titled Hitman: World of Assassination with source year 2016, while its supplied cover is branded HITMAN III. That source naming/edition caveat is retained, not silently corrected.
... A92: 18 / SOURCE IDENTITY | D92: AAA_games_u_have_to_play_list_top_100.xlsx SHA-256: 301043fb513209b129586f617f1d205526c3c61785c48182760cf1aacaf29143 The original attachment is never modified. Generated document timestamps are omitted: no document or critic verification date is invented.
A99: Curated by Leul Tewodros Agonafer
A100: GitHub · LeulTew/play-100 | F100: LinkedIn · Leul Tewodros Agonafer | K100: Telegram · @fabbin
